<?xml version="1.0" encoding="UTF-8"?>
<sdf version="1.11">
  <model name="hexapod">
    <link name="base_footprint">
      <inertial>
        <pose>0.0053346086884782781 0.00026897665908619727 0.1034918721125776 0 0 0</pose>
        <mass>0.17306470568427351</mass>
        <inertia>
          <ixx>0.00026600000000000018</ixx>
          <ixy>3.9999999999999998e-06</ixy>
          <ixz>-1.000000000000011e-06</ixz>
          <iyy>0.00040600000000000011</iyy>
          <iyz>-8.4703294725430034e-22</iyz>
          <izz>0.00059999999999999995</izz>
        </inertia>
      </inertial>
      <collision name="base_footprint_fixed_joint_lump__base_link_collision">
        <pose>0 0 0.085000000000000006 0 0 0</pose>
        <geometry>
          <mesh>
            <scale>0.001 0.001 0.001</scale>
            <uri>file:///home/thurdparty/Code/hexapod-ros/install/hexapod_description/share/hexapod_description/meshes/collision/base_link.stl</uri>
          </mesh>
        </geometry>
        <surface>
          <contact>
            <ode></ode>
          </contact>
          <friction>
            <ode>
              <mu>0.050000000000000003</mu>
              <mu2>0.050000000000000003</mu2>
            </ode>
          </friction>
        </surface>
      </collision>
      <visual name="base_footprint_fixed_joint_lump__base_link_visual">
        <pose>0 0 0.085000000000000006 0 0 0</pose>
        <geometry>
          <mesh>
            <scale>0.001 0.001 0.001</scale>
            <uri>file:///home/thurdparty/Code/hexapod-ros/install/hexapod_description/share/hexapod_description/meshes/visual/base_link.stl</uri>
          </mesh>
        </geometry>
        <material>
          <diffuse>0.37500003 0.37500003 0.37500003 1</diffuse>
          <ambient>0.37500003 0.37500003 0.37500003 1</ambient>
        </material>
      </visual>
      <self_collide>false</self_collide>
    </link>
    <joint name="bottom_left_rotate_joint" type="revolute">
      <pose relative_to="base_footprint">-0.067095000000000002 0.047400999999999999 0.1147 0 0 0.78539816339744839</pose>
      <parent>base_footprint</parent>
      <child>bottom_left_cox</child>
      <axis>
        <xyz>0 0 -1</xyz>
        <limit>
          <lower>-1.5707960000000001</lower>
          <upper>1.5707960000000001</upper>
          <effort>100</effort>
          <velocity>100</velocity>
        </limit>
        <dynamics>
          <spring_reference>0</spring_reference>
          <spring_stiffness>0</spring_stiffness>
        </dynamics>
      </axis>
    </joint>
    <link name="bottom_left_cox">
      <pose relative_to="bottom_left_rotate_joint">0 0 0 0 0 0</pose>
      <inertial>
        <pose>0.0012733261090569091 0.014903434394979129 -0.020345821820411621 0 0 0</pose>
        <mass>0.01391683496290758</mass>
        <inertia>
          <ixx>3.0000000000000001e-06</ixx>
          <ixy>0</ixy>
          <ixz>0</ixz>
          <iyy>3.9999999999999998e-06</iyy>
          <iyz>0</iyz>
          <izz>3.0000000000000001e-06</izz>
        </inertia>
      </inertial>
      <collision name="bottom_left_cox_collision">
        <pose>-0.0036120000000000002 -0.056729000000000002 -0.030599999999999999 0 0 0</pose>
        <geometry>
          <mesh>
            <scale>0.001 0.001 0.001</scale>
            <uri>file:///home/thurdparty/Code/hexapod-ros/install/hexapod_description/share/hexapod_description/meshes/collision/cox_left.stl</uri>
          </mesh>
        </geometry>
      </collision>
      <visual name="bottom_left_cox_visual">
        <pose>-0.0036120000000000002 -0.056729000000000002 -0.030599999999999999 0 0 0</pose>
        <geometry>
          <mesh>
            <scale>0.001 0.001 0.001</scale>
            <uri>file:///home/thurdparty/Code/hexapod-ros/install/hexapod_description/share/hexapod_description/meshes/visual/cox_left.stl</uri>
          </mesh>
        </geometry>
        <material>
          <diffuse>0.37500003 0.37500003 0.37500003 1</diffuse>
          <ambient>0.37500003 0.37500003 0.37500003 1</ambient>
        </material>
      </visual>
    </link>
    <joint name="bottom_left_abduct_joint" type="revolute">
      <pose relative_to="bottom_left_cox">0.020937000000000001 0.029999999999999999 -0.021804 0 0 0</pose>
      <parent>bottom_left_cox</parent>
      <child>bottom_left_femur</child>
      <axis>
        <xyz>-1 0 0</xyz>
        <limit>
          <lower>-1.5707960000000001</lower>
          <upper>1.5707960000000001</upper>
          <effort>100</effort>
          <velocity>100</velocity>
        </limit>
        <dynamics>
          <spring_reference>0</spring_reference>
          <spring_stiffness>0</spring_stiffness>
        </dynamics>
      </axis>
    </joint>
    <link name="bottom_left_femur">
      <pose relative_to="bottom_left_abduct_joint">0 0 0 0 0 0</pose>
      <inertial>
        <pose>-0.01501165493471714 0.020989624323966821 -0.0057282527349048016 0 0 0</pose>
        <mass>0.01882378454979923</mass>
        <inertia>
          <ixx>5.0000000000000004e-06</ixx>
          <ixy>0</ixy>
          <ixz>0</ixz>
          <iyy>3.0000000000000001e-06</iyy>
          <iyz>1.9999999999999999e-06</iyz>
          <izz>5.0000000000000004e-06</izz>
        </inertia>
      </inertial>
      <collision name="bottom_left_femur_collision">
        <pose>-0.024549000000000001 -0.086729000000000001 -0.008796 0 0 0</pose>
        <geometry>
          <mesh>
            <scale>0.001 0.001 0.001</scale>
            <uri>file:///home/thurdparty/Code/hexapod-ros/install/hexapod_description/share/hexapod_description/meshes/collision/femur_left.stl</uri>
          </mesh>
        </geometry>
      </collision>
      <visual name="bottom_left_femur_visual">
        <pose>-0.024549000000000001 -0.086729000000000001 -0.008796 0 0 0</pose>
        <geometry>
          <mesh>
            <scale>0.001 0.001 0.001</scale>
            <uri>file:///home/thurdparty/Code/hexapod-ros/install/hexapod_description/share/hexapod_description/meshes/visual/femur_left.stl</uri>
          </mesh>
        </geometry>
        <material>
          <diffuse>0.37500003 0.37500003 0.37500003 1</diffuse>
          <ambient>0.37500003 0.37500003 0.37500003 1</ambient>
        </material>
      </visual>
    </link>
    <joint name="bottom_left_retract_joint" type="revolute">
      <pose relative_to="bottom_left_femur">-0.029923000000000002 0.039696000000000002 -0.018563 0 0 0</pose>
      <parent>bottom_left_femur</parent>
      <child>bottom_left_tibia</child>
      <axis>
        <xyz>1 0.00011 0</xyz>
        <limit>
          <lower>-1.5707960000000001</lower>
          <upper>1.5707960000000001</upper>
          <effort>100</effort>
          <velocity>100</velocity>
        </limit>
        <dynamics>
          <spring_reference>0</spring_reference>
          <spring_stiffness>0</spring_stiffness>
        </dynamics>
      </axis>
    </joint>
    <link name="bottom_left_tibia">
      <pose relative_to="bottom_left_retract_joint">0 0 0 0 0 0</pose>
      <inertial>
        <pose>0.015773574057860749 0.0058949324510389556 -0.043764578888882869 0 0 0</pose>
        <mass>0.02227943835487755</mass>
        <inertia>
          <ixx>1.939875416507577e-05</ixx>
          <ixy>2.4217580481392058e-08</ixy>
          <ixz>1.0778044150611289e-07</ixz>
          <iyy>1.9769186821995458e-05</iyy>
          <iyz>-3.8060319246942551e-06</iyz>
          <izz>3.9114277506498263e-06</izz>
        </inertia>
      </inertial>
      <collision name="bottom_left_tibia_collision">
        <pose>0.0053740000000000003 -0.12642500000000001 0.0097669999999999996 0 0 0</pose>
        <geometry>
          <mesh>
            <scale>0.001 0.001 0.001</scale>
            <uri>file:///home/thurdparty/Code/hexapod-ros/install/hexapod_description/share/hexapod_description/meshes/collision/tibia_left.stl</uri>
          </mesh>
        </geometry>
      </collision>
      <collision name="bottom_left_tibia_fixed_joint_lump__foot_collision_collision_1">
        <pose>0.016 0 -0.070000000000000007 0 0 0</pose>
        <geometry>
          <sphere>
            <radius>0.0080000000000000002</radius>
          </sphere>
        </geometry>
      </collision>
      <visual name="bottom_left_tibia_visual">
        <pose>0.0053740000000000003 -0.12642500000000001 0.0097669999999999996 0 0 0</pose>
        <geometry>
          <mesh>
            <scale>0.001 0.001 0.001</scale>
            <uri>file:///home/thurdparty/Code/hexapod-ros/install/hexapod_description/share/hexapod_description/meshes/visual/tibia_left.stl</uri>
          </mesh>
        </geometry>
        <material>
          <diffuse>0.37500003 0.37500003 0.37500003 1</diffuse>
          <ambient>0.37500003 0.37500003 0.37500003 1</ambient>
        </material>
      </visual>
      <visual name="bottom_left_tibia_fixed_joint_lump__bottom_left_foot_visual_1">
        <pose>0.016 0 -0.070000000000000007 0 0 0</pose>
        <geometry>
          <sphere>
            <radius>0.0080000000000000002</radius>
          </sphere>
        </geometry>
        <material>
          <diffuse>0.37500003 0.37500003 0.37500003 1</diffuse>
          <ambient>0.37500003 0.37500003 0.37500003 1</ambient>
        </material>
      </visual>
    </link>
    <joint name="bottom_right_rotate_joint" type="revolute">
      <pose relative_to="base_footprint">-0.067095000000000002 -0.046740999999999998 0.1147 0 0 2.3561944901923448</pose>
      <parent>base_footprint</parent>
      <child>bottom_right_cox</child>
      <axis>
        <xyz>0 0 -1</xyz>
        <limit>
          <lower>-1.5707960000000001</lower>
          <upper>1.5707960000000001</upper>
          <effort>100</effort>
          <velocity>100</velocity>
        </limit>
        <dynamics>
          <spring_reference>0</spring_reference>
          <spring_stiffness>0</spring_stiffness>
        </dynamics>
      </axis>
    </joint>
    <link name="bottom_right_cox">
      <pose relative_to="bottom_right_rotate_joint">0 0 0 0 0 0</pose>
      <inertial>
        <pose>0.0012733261090569091 0.014903434394979129 -0.020345821820411621 0 0 0</pose>
        <mass>0.01391683496290758</mass>
        <inertia>
          <ixx>3.0000000000000001e-06</ixx>
          <ixy>0</ixy>
          <ixz>0</ixz>
          <iyy>3.9999999999999998e-06</iyy>
          <iyz>0</iyz>
          <izz>3.0000000000000001e-06</izz>
        </inertia>
      </inertial>
      <collision name="bottom_right_cox_collision">
        <pose>0.0035000000000000001 -0.055 -0.030599999999999999 0 0 3.1415926535897931</pose>
        <geometry>
          <mesh>
            <scale>0.001 0.001 0.001</scale>
            <uri>file:///home/thurdparty/Code/hexapod-ros/install/hexapod_description/share/hexapod_description/meshes/collision/cox_right.stl</uri>
          </mesh>
        </geometry>
      </collision>
      <visual name="bottom_right_cox_visual">
        <pose>0.0035000000000000001 -0.055 -0.030599999999999999 0 0 3.1415926535897931</pose>
        <geometry>
          <mesh>
            <scale>0.001 0.001 0.001</scale>
            <uri>file:///home/thurdparty/Code/hexapod-ros/install/hexapod_description/share/hexapod_description/meshes/visual/cox_right.stl</uri>
          </mesh>
        </geometry>
        <material>
          <diffuse>0.37500003 0.37500003 0.37500003 1</diffuse>
          <ambient>0.37500003 0.37500003 0.37500003 1</ambient>
        </material>
      </visual>
    </link>
    <joint name="bottom_right_abduct_joint" type="revolute">
      <pose relative_to="bottom_right_cox">0.0077499999999999999 0.029999999999999999 -0.021804 0 0 0</pose>
      <parent>bottom_right_cox</parent>
      <child>bottom_right_femur</child>
      <axis>
        <xyz>-1 0 0</xyz>
        <limit>
          <lower>-1.5707960000000001</lower>
          <upper>1.5707960000000001</upper>
          <effort>100</effort>
          <velocity>100</velocity>
        </limit>
        <dynamics>
          <spring_reference>0</spring_reference>
          <spring_stiffness>0</spring_stiffness>
        </dynamics>
      </axis>
    </joint>
    <link name="bottom_right_femur">
      <pose relative_to="bottom_right_abduct_joint">0 0 0 0 0 0</pose>
      <inertial>
        <pose>-0.01501165493471714 0.020989624323966821 -0.0057282527349048016 0 0 0</pose>
        <mass>0.01882378454979923</mass>
        <inertia>
          <ixx>5.0000000000000004e-06</ixx>
          <ixy>0</ixy>
          <ixz>0</ixz>
          <iyy>3.0000000000000001e-06</iyy>
          <iyz>1.9999999999999999e-06</iyz>
          <izz>5.0000000000000004e-06</izz>
        </inertia>
      </inertial>
      <collision name="bottom_right_femur_collision">
        <pose>-0.0035000000000000001 -0.085000000000000006 -0.0085000000000000006 0 0 3.1415926535897931</pose>
        <geometry>
          <mesh>
            <scale>0.001 0.001 0.001</scale>
            <uri>file:///home/thurdparty/Code/hexapod-ros/install/hexapod_description/share/hexapod_description/meshes/collision/femur_right.stl</uri>
          </mesh>
        </geometry>
      </collision>
      <visual name="bottom_right_femur_visual">
        <pose>-0.0035000000000000001 -0.085000000000000006 -0.0085000000000000006 0 0 3.1415926535897931</pose>
        <geometry>
          <mesh>
            <scale>0.001 0.001 0.001</scale>
            <uri>file:///home/thurdparty/Code/hexapod-ros/install/hexapod_description/share/hexapod_description/meshes/visual/femur_right.stl</uri>
          </mesh>
        </geometry>
        <material>
          <diffuse>0.37500003 0.37500003 0.37500003 1</diffuse>
          <ambient>0.37500003 0.37500003 0.37500003 1</ambient>
        </material>
      </visual>
    </link>
    <joint name="bottom_right_retract_joint" type="revolute">
      <pose relative_to="bottom_right_femur">-0.029923000000000002 0.039696000000000002 -0.018563 0 0 0</pose>
      <parent>bottom_right_femur</parent>
      <child>bottom_right_tibia</child>
      <axis>
        <xyz>1 0.00011 0</xyz>
        <limit>
          <lower>-1.5707960000000001</lower>
          <upper>1.5707960000000001</upper>
          <effort>100</effort>
          <velocity>100</velocity>
        </limit>
        <dynamics>
          <spring_reference>0</spring_reference>
          <spring_stiffness>0</spring_stiffness>
        </dynamics>
      </axis>
    </joint>
    <link name="bottom_right_tibia">
      <pose relative_to="bottom_right_retract_joint">0 0 0 0 0 0</pose>
      <inertial>
        <pose>0.015773574057860749 0.0058949324510389556 -0.043764578888882869 0 0 0</pose>
        <mass>0.02227943835487755</mass>
        <inertia>
          <ixx>1.939875416507577e-05</ixx>
          <ixy>2.4217580481392058e-08</ixy>
          <ixz>1.0778044150611289e-07</ixz>
          <iyy>1.9769186821995458e-05</iyy>
          <iyz>-3.8060319246942551e-06</iyz>
          <izz>3.9114277506498263e-06</izz>
        </inertia>
      </inertial>
      <collision name="bottom_right_tibia_collision">
        <pose>0.0275 -0.125 0.01 0 0 3.1415926535897931</pose>
        <geometry>
          <mesh>
            <scale>0.001 0.001 0.001</scale>
            <uri>file:///home/thurdparty/Code/hexapod-ros/install/hexapod_description/share/hexapod_description/meshes/collision/tibia_right.stl</uri>
          </mesh>
        </geometry>
      </collision>
      <collision name="bottom_right_tibia_fixed_joint_lump__foot_collision_collision_1">
        <pose>0.016 0 -0.070000000000000007 0 0 0</pose>
        <geometry>
          <sphere>
            <radius>0.0080000000000000002</radius>
          </sphere>
        </geometry>
      </collision>
      <visual name="bottom_right_tibia_visual">
        <pose>0.0275 -0.125 0.01 0 0 3.1415926535897931</pose>
        <geometry>
          <mesh>
            <scale>0.001 0.001 0.001</scale>
            <uri>file:///home/thurdparty/Code/hexapod-ros/install/hexapod_description/share/hexapod_description/meshes/visual/tibia_right.stl</uri>
          </mesh>
        </geometry>
        <material>
          <diffuse>0.37500003 0.37500003 0.37500003 1</diffuse>
          <ambient>0.37500003 0.37500003 0.37500003 1</ambient>
        </material>
      </visual>
      <visual name="bottom_right_tibia_fixed_joint_lump__bottom_right_foot_visual_1">
        <pose>0.016 0 -0.070000000000000007 0 0 0</pose>
        <geometry>
          <sphere>
            <radius>0.0080000000000000002</radius>
          </sphere>
        </geometry>
        <material>
          <diffuse>0.37500003 0.37500003 0.37500003 1</diffuse>
          <ambient>0.37500003 0.37500003 0.37500003 1</ambient>
        </material>
      </visual>
    </link>
    <joint name="mid_left_rotate_joint" type="revolute">
      <pose relative_to="base_footprint">0.0036120000000000002 0.056729000000000002 0.11559999999999999 0 0 0</pose>
      <parent>base_footprint</parent>
      <child>mid_left_cox</child>
      <axis>
        <xyz>0 0 -1</xyz>
        <limit>
          <lower>-1.5707960000000001</lower>
          <upper>1.5707960000000001</upper>
          <effort>100</effort>
          <velocity>100</velocity>
        </limit>
        <dynamics>
          <spring_reference>0</spring_reference>
          <spring_stiffness>0</spring_stiffness>
        </dynamics>
      </axis>
    </joint>
    <link name="mid_left_cox">
      <pose relative_to="mid_left_rotate_joint">0 0 0 0 0 0</pose>
      <inertial>
        <pose>0.0012733261090569091 0.014903434394979129 -0.020345821820411621 0 0 0</pose>
        <mass>0.01391683496290758</mass>
        <inertia>
          <ixx>3.0000000000000001e-06</ixx>
          <ixy>0</ixy>
          <ixz>0</ixz>
          <iyy>3.9999999999999998e-06</iyy>
          <iyz>0</iyz>
          <izz>3.0000000000000001e-06</izz>
        </inertia>
      </inertial>
      <collision name="mid_left_cox_collision">
        <pose>-0.0036120000000000002 -0.056729000000000002 -0.030599999999999999 0 0 0</pose>
        <geometry>
          <mesh>
            <scale>0.001 0.001 0.001</scale>
            <uri>file:///home/thurdparty/Code/hexapod-ros/install/hexapod_description/share/hexapod_description/meshes/collision/cox_left.stl</uri>
          </mesh>
        </geometry>
      </collision>
      <visual name="mid_left_cox_visual">
        <pose>-0.0036120000000000002 -0.056729000000000002 -0.030599999999999999 0 0 0</pose>
        <geometry>
          <mesh>
            <scale>0.001 0.001 0.001</scale>
            <uri>file:///home/thurdparty/Code/hexapod-ros/install/hexapod_description/share/hexapod_description/meshes/visual/cox_left.stl</uri>
          </mesh>
        </geometry>
        <material>
          <diffuse>0.37500003 0.37500003 0.37500003 1</diffuse>
          <ambient>0.37500003 0.37500003 0.37500003 1</ambient>
        </material>
      </visual>
    </link>
    <joint name="mid_left_abduct_joint" type="revolute">
      <pose relative_to="mid_left_cox">0.020937000000000001 0.029999999999999999 -0.021804 0 0 0</pose>
      <parent>mid_left_cox</parent>
      <child>mid_left_femur</child>
      <axis>
        <xyz>-1 0 0</xyz>
        <limit>
          <lower>-1.5707960000000001</lower>
          <upper>1.5707960000000001</upper>
          <effort>100</effort>
          <velocity>100</velocity>
        </limit>
        <dynamics>
          <spring_reference>0</spring_reference>
          <spring_stiffness>0</spring_stiffness>
        </dynamics>
      </axis>
    </joint>
    <link name="mid_left_femur">
      <pose relative_to="mid_left_abduct_joint">0 0 0 0 0 0</pose>
      <inertial>
        <pose>-0.01501165493471714 0.020989624323966821 -0.0057282527349048016 0 0 0</pose>
        <mass>0.01882378454979923</mass>
        <inertia>
          <ixx>5.0000000000000004e-06</ixx>
          <ixy>0</ixy>
          <ixz>0</ixz>
          <iyy>3.0000000000000001e-06</iyy>
          <iyz>1.9999999999999999e-06</iyz>
          <izz>5.0000000000000004e-06</izz>
        </inertia>
      </inertial>
      <collision name="mid_left_femur_collision">
        <pose>-0.024549000000000001 -0.086729000000000001 -0.008796 0 0 0</pose>
        <geometry>
          <mesh>
            <scale>0.001 0.001 0.001</scale>
            <uri>file:///home/thurdparty/Code/hexapod-ros/install/hexapod_description/share/hexapod_description/meshes/collision/femur_left.stl</uri>
          </mesh>
        </geometry>
      </collision>
      <visual name="mid_left_femur_visual">
        <pose>-0.024549000000000001 -0.086729000000000001 -0.008796 0 0 0</pose>
        <geometry>
          <mesh>
            <scale>0.001 0.001 0.001</scale>
            <uri>file:///home/thurdparty/Code/hexapod-ros/install/hexapod_description/share/hexapod_description/meshes/visual/femur_left.stl</uri>
          </mesh>
        </geometry>
        <material>
          <diffuse>0.37500003 0.37500003 0.37500003 1</diffuse>
          <ambient>0.37500003 0.37500003 0.37500003 1</ambient>
        </material>
      </visual>
    </link>
    <joint name="mid_left_retract_joint" type="revolute">
      <pose relative_to="mid_left_femur">-0.029923000000000002 0.039696000000000002 -0.018563 0 0 0</pose>
      <parent>mid_left_femur</parent>
      <child>mid_left_tibia</child>
      <axis>
        <xyz>1 0.00011 0</xyz>
        <limit>
          <lower>-1.5707960000000001</lower>
          <upper>1.5707960000000001</upper>
          <effort>100</effort>
          <velocity>100</velocity>
        </limit>
        <dynamics>
          <spring_reference>0</spring_reference>
          <spring_stiffness>0</spring_stiffness>
        </dynamics>
      </axis>
    </joint>
    <link name="mid_left_tibia">
      <pose relative_to="mid_left_retract_joint">0 0 0 0 0 0</pose>
      <inertial>
        <pose>0.015773574057860749 0.0058949324510389556 -0.043764578888882869 0 0 0</pose>
        <mass>0.02227943835487755</mass>
        <inertia>
          <ixx>1.939875416507577e-05</ixx>
          <ixy>2.4217580481392058e-08</ixy>
          <ixz>1.0778044150611289e-07</ixz>
          <iyy>1.9769186821995458e-05</iyy>
          <iyz>-3.8060319246942551e-06</iyz>
          <izz>3.9114277506498263e-06</izz>
        </inertia>
      </inertial>
      <collision name="mid_left_tibia_collision">
        <pose>0.0053740000000000003 -0.12642500000000001 0.0097669999999999996 0 0 0</pose>
        <geometry>
          <mesh>
            <scale>0.001 0.001 0.001</scale>
            <uri>file:///home/thurdparty/Code/hexapod-ros/install/hexapod_description/share/hexapod_description/meshes/collision/tibia_left.stl</uri>
          </mesh>
        </geometry>
      </collision>
      <collision name="mid_left_tibia_fixed_joint_lump__foot_collision_collision_1">
        <pose>0.016 0 -0.070000000000000007 0 0 0</pose>
        <geometry>
          <sphere>
            <radius>0.0080000000000000002</radius>
          </sphere>
        </geometry>
      </collision>
      <visual name="mid_left_tibia_visual">
        <pose>0.0053740000000000003 -0.12642500000000001 0.0097669999999999996 0 0 0</pose>
        <geometry>
          <mesh>
            <scale>0.001 0.001 0.001</scale>
            <uri>file:///home/thurdparty/Code/hexapod-ros/install/hexapod_description/share/hexapod_description/meshes/visual/tibia_left.stl</uri>
          </mesh>
        </geometry>
        <material>
          <diffuse>0.37500003 0.37500003 0.37500003 1</diffuse>
          <ambient>0.37500003 0.37500003 0.37500003 1</ambient>
        </material>
      </visual>
      <visual name="mid_left_tibia_fixed_joint_lump__mid_left_foot_visual_1">
        <pose>0.016 0 -0.070000000000000007 0 0 0</pose>
        <geometry>
          <sphere>
            <radius>0.0080000000000000002</radius>
          </sphere>
        </geometry>
        <material>
          <diffuse>0.37500003 0.37500003 0.37500003 1</diffuse>
          <ambient>0.37500003 0.37500003 0.37500003 1</ambient>
        </material>
      </visual>
    </link>
    <joint name="mid_right_rotate_joint" type="revolute">
      <pose relative_to="base_footprint">0.0035739999999999999 -0.054899000000000003 0.11559999999999999 0 0 3.1415926535897931</pose>
      <parent>base_footprint</parent>
      <child>mid_right_cox</child>
      <axis>
        <xyz>0 0 -1</xyz>
        <limit>
          <lower>-1.5707960000000001</lower>
          <upper>1.5707960000000001</upper>
          <effort>100</effort>
          <velocity>100</velocity>
        </limit>
        <dynamics>
          <spring_reference>0</spring_reference>
          <spring_stiffness>0</spring_stiffness>
        </dynamics>
      </axis>
    </joint>
    <link name="mid_right_cox">
      <pose relative_to="mid_right_rotate_joint">0 0 0 0 0 0</pose>
      <inertial>
        <pose>0.0012733261090569091 0.014903434394979129 -0.020345821820411621 0 0 0</pose>
        <mass>0.01391683496290758</mass>
        <inertia>
          <ixx>3.0000000000000001e-06</ixx>
          <ixy>0</ixy>
          <ixz>0</ixz>
          <iyy>3.9999999999999998e-06</iyy>
          <iyz>0</iyz>
          <izz>3.0000000000000001e-06</izz>
        </inertia>
      </inertial>
      <collision name="mid_right_cox_collision">
        <pose>0.0035000000000000001 -0.055 -0.030599999999999999 0 0 3.1415926535897931</pose>
        <geometry>
          <mesh>
            <scale>0.001 0.001 0.001</scale>
            <uri>file:///home/thurdparty/Code/hexapod-ros/install/hexapod_description/share/hexapod_description/meshes/collision/cox_right.stl</uri>
          </mesh>
        </geometry>
      </collision>
      <visual name="mid_right_cox_visual">
        <pose>0.0035000000000000001 -0.055 -0.030599999999999999 0 0 3.1415926535897931</pose>
        <geometry>
          <mesh>
            <scale>0.001 0.001 0.001</scale>
            <uri>file:///home/thurdparty/Code/hexapod-ros/install/hexapod_description/share/hexapod_description/meshes/visual/cox_right.stl</uri>
          </mesh>
        </geometry>
        <material>
          <diffuse>0.37500003 0.37500003 0.37500003 1</diffuse>
          <ambient>0.37500003 0.37500003 0.37500003 1</ambient>
        </material>
      </visual>
    </link>
    <joint name="mid_right_abduct_joint" type="revolute">
      <pose relative_to="mid_right_cox">0.0077499999999999999 0.029999999999999999 -0.021804 0 0 0</pose>
      <parent>mid_right_cox</parent>
      <child>mid_right_femur</child>
      <axis>
        <xyz>-1 0 0</xyz>
        <limit>
          <lower>-1.5707960000000001</lower>
          <upper>1.5707960000000001</upper>
          <effort>100</effort>
          <velocity>100</velocity>
        </limit>
        <dynamics>
          <spring_reference>0</spring_reference>
          <spring_stiffness>0</spring_stiffness>
        </dynamics>
      </axis>
    </joint>
    <link name="mid_right_femur">
      <pose relative_to="mid_right_abduct_joint">0 0 0 0 0 0</pose>
      <inertial>
        <pose>-0.01501165493471714 0.020989624323966821 -0.0057282527349048016 0 0 0</pose>
        <mass>0.01882378454979923</mass>
        <inertia>
          <ixx>5.0000000000000004e-06</ixx>
          <ixy>0</ixy>
          <ixz>0</ixz>
          <iyy>3.0000000000000001e-06</iyy>
          <iyz>1.9999999999999999e-06</iyz>
          <izz>5.0000000000000004e-06</izz>
        </inertia>
      </inertial>
      <collision name="mid_right_femur_collision">
        <pose>-0.0035000000000000001 -0.085000000000000006 -0.0085000000000000006 0 0 3.1415926535897931</pose>
        <geometry>
          <mesh>
            <scale>0.001 0.001 0.001</scale>
            <uri>file:///home/thurdparty/Code/hexapod-ros/install/hexapod_description/share/hexapod_description/meshes/collision/femur_right.stl</uri>
          </mesh>
        </geometry>
      </collision>
      <visual name="mid_right_femur_visual">
        <pose>-0.0035000000000000001 -0.085000000000000006 -0.0085000000000000006 0 0 3.1415926535897931</pose>
        <geometry>
          <mesh>
            <scale>0.001 0.001 0.001</scale>
            <uri>file:///home/thurdparty/Code/hexapod-ros/install/hexapod_description/share/hexapod_description/meshes/visual/femur_right.stl</uri>
          </mesh>
        </geometry>
        <material>
          <diffuse>0.37500003 0.37500003 0.37500003 1</diffuse>
          <ambient>0.37500003 0.37500003 0.37500003 1</ambient>
        </material>
      </visual>
    </link>
    <joint name="mid_right_retract_joint" type="revolute">
      <pose relative_to="mid_right_femur">-0.029923000000000002 0.039696000000000002 -0.018563 0 0 0</pose>
      <parent>mid_right_femur</parent>
      <child>mid_right_tibia</child>
      <axis>
        <xyz>1 0.00011 0</xyz>
        <limit>
          <lower>-1.5707960000000001</lower>
          <upper>1.5707960000000001</upper>
          <effort>100</effort>
          <velocity>100</velocity>
        </limit>
        <dynamics>
          <spring_reference>0</spring_reference>
          <spring_stiffness>0</spring_stiffness>
        </dynamics>
      </axis>
    </joint>
    <link name="mid_right_tibia">
      <pose relative_to="mid_right_retract_joint">0 0 0 0 0 0</pose>
      <inertial>
        <pose>0.015773574057860749 0.0058949324510389556 -0.043764578888882869 0 0 0</pose>
        <mass>0.02227943835487755</mass>
        <inertia>
          <ixx>1.939875416507577e-05</ixx>
          <ixy>2.4217580481392058e-08</ixy>
          <ixz>1.0778044150611289e-07</ixz>
          <iyy>1.9769186821995458e-05</iyy>
          <iyz>-3.8060319246942551e-06</iyz>
          <izz>3.9114277506498263e-06</izz>
        </inertia>
      </inertial>
      <collision name="mid_right_tibia_collision">
        <pose>0.0275 -0.125 0.01 0 0 3.1415926535897931</pose>
        <geometry>
          <mesh>
            <scale>0.001 0.001 0.001</scale>
            <uri>file:///home/thurdparty/Code/hexapod-ros/install/hexapod_description/share/hexapod_description/meshes/collision/tibia_right.stl</uri>
          </mesh>
        </geometry>
      </collision>
      <collision name="mid_right_tibia_fixed_joint_lump__foot_collision_collision_1">
        <pose>0.016 0 -0.070000000000000007 0 0 0</pose>
        <geometry>
          <sphere>
            <radius>0.0080000000000000002</radius>
          </sphere>
        </geometry>
      </collision>
      <visual name="mid_right_tibia_visual">
        <pose>0.0275 -0.125 0.01 0 0 3.1415926535897931</pose>
        <geometry>
          <mesh>
            <scale>0.001 0.001 0.001</scale>
            <uri>file:///home/thurdparty/Code/hexapod-ros/install/hexapod_description/share/hexapod_description/meshes/visual/tibia_right.stl</uri>
          </mesh>
        </geometry>
        <material>
          <diffuse>0.37500003 0.37500003 0.37500003 1</diffuse>
          <ambient>0.37500003 0.37500003 0.37500003 1</ambient>
        </material>
      </visual>
      <visual name="mid_right_tibia_fixed_joint_lump__mid_right_foot_visual_1">
        <pose>0.016 0 -0.070000000000000007 0 0 0</pose>
        <geometry>
          <sphere>
            <radius>0.0080000000000000002</radius>
          </sphere>
        </geometry>
        <material>
          <diffuse>0.37500003 0.37500003 0.37500003 1</diffuse>
          <ambient>0.37500003 0.37500003 0.37500003 1</ambient>
        </material>
      </visual>
    </link>
    <joint name="top_left_rotate_joint" type="revolute">
      <pose relative_to="base_footprint">0.074451000000000003 0.046823999999999998 0.1147 0 0 -0.78539816339744839</pose>
      <parent>base_footprint</parent>
      <child>top_left_cox</child>
      <axis>
        <xyz>0 0 -1</xyz>
        <limit>
          <lower>-1.5707960000000001</lower>
          <upper>1.5707960000000001</upper>
          <effort>100</effort>
          <velocity>100</velocity>
        </limit>
        <dynamics>
          <spring_reference>0</spring_reference>
          <spring_stiffness>0</spring_stiffness>
        </dynamics>
      </axis>
    </joint>
    <link name="top_left_cox">
      <pose relative_to="top_left_rotate_joint">0 0 0 0 0 0</pose>
      <inertial>
        <pose>0.0012733261090569091 0.014903434394979129 -0.020345821820411621 0 0 0</pose>
        <mass>0.01391683496290758</mass>
        <inertia>
          <ixx>3.0000000000000001e-06</ixx>
          <ixy>0</ixy>
          <ixz>0</ixz>
          <iyy>3.9999999999999998e-06</iyy>
          <iyz>0</iyz>
          <izz>3.0000000000000001e-06</izz>
        </inertia>
      </inertial>
      <collision name="top_left_cox_collision">
        <pose>-0.0036120000000000002 -0.056729000000000002 -0.030599999999999999 0 0 0</pose>
        <geometry>
          <mesh>
            <scale>0.001 0.001 0.001</scale>
            <uri>file:///home/thurdparty/Code/hexapod-ros/install/hexapod_description/share/hexapod_description/meshes/collision/cox_left.stl</uri>
          </mesh>
        </geometry>
      </collision>
      <visual name="top_left_cox_visual">
        <pose>-0.0036120000000000002 -0.056729000000000002 -0.030599999999999999 0 0 0</pose>
        <geometry>
          <mesh>
            <scale>0.001 0.001 0.001</scale>
            <uri>file:///home/thurdparty/Code/hexapod-ros/install/hexapod_description/share/hexapod_description/meshes/visual/cox_left.stl</uri>
          </mesh>
        </geometry>
        <material>
          <diffuse>0.37500003 0.37500003 0.37500003 1</diffuse>
          <ambient>0.37500003 0.37500003 0.37500003 1</ambient>
        </material>
      </visual>
    </link>
    <joint name="top_left_abduct_joint" type="revolute">
      <pose relative_to="top_left_cox">0.020937000000000001 0.029999999999999999 -0.021804 0 0 0</pose>
      <parent>top_left_cox</parent>
      <child>top_left_femur</child>
      <axis>
        <xyz>-1 0 0</xyz>
        <limit>
          <lower>-1.5707960000000001</lower>
          <upper>1.5707960000000001</upper>
          <effort>100</effort>
          <velocity>100</velocity>
        </limit>
        <dynamics>
          <spring_reference>0</spring_reference>
          <spring_stiffness>0</spring_stiffness>
        </dynamics>
      </axis>
    </joint>
    <link name="top_left_femur">
      <pose relative_to="top_left_abduct_joint">0 0 0 0 0 0</pose>
      <inertial>
        <pose>-0.01501165493471714 0.020989624323966821 -0.0057282527349048016 0 0 0</pose>
        <mass>0.01882378454979923</mass>
        <inertia>
          <ixx>5.0000000000000004e-06</ixx>
          <ixy>0</ixy>
          <ixz>0</ixz>
          <iyy>3.0000000000000001e-06</iyy>
          <iyz>1.9999999999999999e-06</iyz>
          <izz>5.0000000000000004e-06</izz>
        </inertia>
      </inertial>
      <collision name="top_left_femur_collision">
        <pose>-0.024549000000000001 -0.086729000000000001 -0.008796 0 0 0</pose>
        <geometry>
          <mesh>
            <scale>0.001 0.001 0.001</scale>
            <uri>file:///home/thurdparty/Code/hexapod-ros/install/hexapod_description/share/hexapod_description/meshes/collision/femur_left.stl</uri>
          </mesh>
        </geometry>
      </collision>
      <visual name="top_left_femur_visual">
        <pose>-0.024549000000000001 -0.086729000000000001 -0.008796 0 0 0</pose>
        <geometry>
          <mesh>
            <scale>0.001 0.001 0.001</scale>
            <uri>file:///home/thurdparty/Code/hexapod-ros/install/hexapod_description/share/hexapod_description/meshes/visual/femur_left.stl</uri>
          </mesh>
        </geometry>
        <material>
          <diffuse>0.37500003 0.37500003 0.37500003 1</diffuse>
          <ambient>0.37500003 0.37500003 0.37500003 1</ambient>
        </material>
      </visual>
    </link>
    <joint name="top_left_retract_joint" type="revolute">
      <pose relative_to="top_left_femur">-0.029923000000000002 0.039696000000000002 -0.018563 0 0 0</pose>
      <parent>top_left_femur</parent>
      <child>top_left_tibia</child>
      <axis>
        <xyz>1 0.00011 0</xyz>
        <limit>
          <lower>-1.5707960000000001</lower>
          <upper>1.5707960000000001</upper>
          <effort>100</effort>
          <velocity>100</velocity>
        </limit>
        <dynamics>
          <spring_reference>0</spring_reference>
          <spring_stiffness>0</spring_stiffness>
        </dynamics>
      </axis>
    </joint>
    <link name="top_left_tibia">
      <pose relative_to="top_left_retract_joint">0 0 0 0 0 0</pose>
      <inertial>
        <pose>0.015773574057860749 0.0058949324510389556 -0.043764578888882869 0 0 0</pose>
        <mass>0.02227943835487755</mass>
        <inertia>
          <ixx>1.939875416507577e-05</ixx>
          <ixy>2.4217580481392058e-08</ixy>
          <ixz>1.0778044150611289e-07</ixz>
          <iyy>1.9769186821995458e-05</iyy>
          <iyz>-3.8060319246942551e-06</iyz>
          <izz>3.9114277506498263e-06</izz>
        </inertia>
      </inertial>
      <collision name="top_left_tibia_collision">
        <pose>0.0053740000000000003 -0.12642500000000001 0.0097669999999999996 0 0 0</pose>
        <geometry>
          <mesh>
            <scale>0.001 0.001 0.001</scale>
            <uri>file:///home/thurdparty/Code/hexapod-ros/install/hexapod_description/share/hexapod_description/meshes/collision/tibia_left.stl</uri>
          </mesh>
        </geometry>
      </collision>
      <collision name="top_left_tibia_fixed_joint_lump__foot_collision_collision_1">
        <pose>0.016 0 -0.070000000000000007 0 0 0</pose>
        <geometry>
          <sphere>
            <radius>0.0080000000000000002</radius>
          </sphere>
        </geometry>
      </collision>
      <visual name="top_left_tibia_visual">
        <pose>0.0053740000000000003 -0.12642500000000001 0.0097669999999999996 0 0 0</pose>
        <geometry>
          <mesh>
            <scale>0.001 0.001 0.001</scale>
            <uri>file:///home/thurdparty/Code/hexapod-ros/install/hexapod_description/share/hexapod_description/meshes/visual/tibia_left.stl</uri>
          </mesh>
        </geometry>
        <material>
          <diffuse>0.37500003 0.37500003 0.37500003 1</diffuse>
          <ambient>0.37500003 0.37500003 0.37500003 1</ambient>
        </material>
      </visual>
      <visual name="top_left_tibia_fixed_joint_lump__top_left_foot_visual_1">
        <pose>0.016 0 -0.070000000000000007 0 0 0</pose>
        <geometry>
          <sphere>
            <radius>0.0080000000000000002</radius>
          </sphere>
        </geometry>
        <material>
          <diffuse>0.37500003 0.37500003 0.37500003 1</diffuse>
          <ambient>0.37500003 0.37500003 0.37500003 1</ambient>
        </material>
      </visual>
    </link>
    <joint name="top_right_rotate_joint" type="revolute">
      <pose relative_to="base_footprint">0.075633000000000006 -0.046740999999999998 0.1147 0 0 -2.3561944901923448</pose>
      <parent>base_footprint</parent>
      <child>top_right_cox</child>
      <axis>
        <xyz>0 0 -1</xyz>
        <limit>
          <lower>-1.5707960000000001</lower>
          <upper>1.5707960000000001</upper>
          <effort>100</effort>
          <velocity>100</velocity>
        </limit>
        <dynamics>
          <spring_reference>0</spring_reference>
          <spring_stiffness>0</spring_stiffness>
        </dynamics>
      </axis>
    </joint>
    <link name="top_right_cox">
      <pose relative_to="top_right_rotate_joint">0 0 0 0 0 0</pose>
      <inertial>
        <pose>0.0012733261090569091 0.014903434394979129 -0.020345821820411621 0 0 0</pose>
        <mass>0.01391683496290758</mass>
        <inertia>
          <ixx>3.0000000000000001e-06</ixx>
          <ixy>0</ixy>
          <ixz>0</ixz>
          <iyy>3.9999999999999998e-06</iyy>
          <iyz>0</iyz>
          <izz>3.0000000000000001e-06</izz>
        </inertia>
      </inertial>
      <collision name="top_right_cox_collision">
        <pose>0.0035000000000000001 -0.055 -0.030599999999999999 0 0 3.1415926535897931</pose>
        <geometry>
          <mesh>
            <scale>0.001 0.001 0.001</scale>
            <uri>file:///home/thurdparty/Code/hexapod-ros/install/hexapod_description/share/hexapod_description/meshes/collision/cox_right.stl</uri>
          </mesh>
        </geometry>
      </collision>
      <visual name="top_right_cox_visual">
        <pose>0.0035000000000000001 -0.055 -0.030599999999999999 0 0 3.1415926535897931</pose>
        <geometry>
          <mesh>
            <scale>0.001 0.001 0.001</scale>
            <uri>file:///home/thurdparty/Code/hexapod-ros/install/hexapod_description/share/hexapod_description/meshes/visual/cox_right.stl</uri>
          </mesh>
        </geometry>
        <material>
          <diffuse>0.37500003 0.37500003 0.37500003 1</diffuse>
          <ambient>0.37500003 0.37500003 0.37500003 1</ambient>
        </material>
      </visual>
    </link>
    <joint name="top_right_abduct_joint" type="revolute">
      <pose relative_to="top_right_cox">0.0077499999999999999 0.029999999999999999 -0.021804 0 0 0</pose>
      <parent>top_right_cox</parent>
      <child>top_right_femur</child>
      <axis>
        <xyz>-1 0 0</xyz>
        <limit>
          <lower>-1.5707960000000001</lower>
          <upper>1.5707960000000001</upper>
          <effort>100</effort>
          <velocity>100</velocity>
        </limit>
        <dynamics>
          <spring_reference>0</spring_reference>
          <spring_stiffness>0</spring_stiffness>
        </dynamics>
      </axis>
    </joint>
    <link name="top_right_femur">
      <pose relative_to="top_right_abduct_joint">0 0 0 0 0 0</pose>
      <inertial>
        <pose>-0.01501165493471714 0.020989624323966821 -0.0057282527349048016 0 0 0</pose>
        <mass>0.01882378454979923</mass>
        <inertia>
          <ixx>5.0000000000000004e-06</ixx>
          <ixy>0</ixy>
          <ixz>0</ixz>
          <iyy>3.0000000000000001e-06</iyy>
          <iyz>1.9999999999999999e-06</iyz>
          <izz>5.0000000000000004e-06</izz>
        </inertia>
      </inertial>
      <collision name="top_right_femur_collision">
        <pose>-0.0035000000000000001 -0.085000000000000006 -0.0085000000000000006 0 0 3.1415926535897931</pose>
        <geometry>
          <mesh>
            <scale>0.001 0.001 0.001</scale>
            <uri>file:///home/thurdparty/Code/hexapod-ros/install/hexapod_description/share/hexapod_description/meshes/collision/femur_right.stl</uri>
          </mesh>
        </geometry>
      </collision>
      <visual name="top_right_femur_visual">
        <pose>-0.0035000000000000001 -0.085000000000000006 -0.0085000000000000006 0 0 3.1415926535897931</pose>
        <geometry>
          <mesh>
            <scale>0.001 0.001 0.001</scale>
            <uri>file:///home/thurdparty/Code/hexapod-ros/install/hexapod_description/share/hexapod_description/meshes/visual/femur_right.stl</uri>
          </mesh>
        </geometry>
        <material>
          <diffuse>0.37500003 0.37500003 0.37500003 1</diffuse>
          <ambient>0.37500003 0.37500003 0.37500003 1</ambient>
        </material>
      </visual>
    </link>
    <joint name="top_right_retract_joint" type="revolute">
      <pose relative_to="top_right_femur">-0.029923000000000002 0.039696000000000002 -0.018563 0 0 0</pose>
      <parent>top_right_femur</parent>
      <child>top_right_tibia</child>
      <axis>
        <xyz>1 0.00011 0</xyz>
        <limit>
          <lower>-1.5707960000000001</lower>
          <upper>1.5707960000000001</upper>
          <effort>100</effort>
          <velocity>100</velocity>
        </limit>
        <dynamics>
          <spring_reference>0</spring_reference>
          <spring_stiffness>0</spring_stiffness>
        </dynamics>
      </axis>
    </joint>
    <link name="top_right_tibia">
      <pose relative_to="top_right_retract_joint">0 0 0 0 0 0</pose>
      <inertial>
        <pose>0.015773574057860749 0.0058949324510389556 -0.043764578888882869 0 0 0</pose>
        <mass>0.02227943835487755</mass>
        <inertia>
          <ixx>1.939875416507577e-05</ixx>
          <ixy>2.4217580481392058e-08</ixy>
          <ixz>1.0778044150611289e-07</ixz>
          <iyy>1.9769186821995458e-05</iyy>
          <iyz>-3.8060319246942551e-06</iyz>
          <izz>3.9114277506498263e-06</izz>
        </inertia>
      </inertial>
      <collision name="top_right_tibia_collision">
        <pose>0.0275 -0.125 0.01 0 0 3.1415926535897931</pose>
        <geometry>
          <mesh>
            <scale>0.001 0.001 0.001</scale>
            <uri>file:///home/thurdparty/Code/hexapod-ros/install/hexapod_description/share/hexapod_description/meshes/collision/tibia_right.stl</uri>
          </mesh>
        </geometry>
      </collision>
      <collision name="top_right_tibia_fixed_joint_lump__foot_collision_collision_1">
        <pose>0.016 0 -0.070000000000000007 0 0 0</pose>
        <geometry>
          <sphere>
            <radius>0.0080000000000000002</radius>
          </sphere>
        </geometry>
      </collision>
      <visual name="top_right_tibia_visual">
        <pose>0.0275 -0.125 0.01 0 0 3.1415926535897931</pose>
        <geometry>
          <mesh>
            <scale>0.001 0.001 0.001</scale>
            <uri>file:///home/thurdparty/Code/hexapod-ros/install/hexapod_description/share/hexapod_description/meshes/visual/tibia_right.stl</uri>
          </mesh>
        </geometry>
        <material>
          <diffuse>0.37500003 0.37500003 0.37500003 1</diffuse>
          <ambient>0.37500003 0.37500003 0.37500003 1</ambient>
        </material>
      </visual>
      <visual name="top_right_tibia_fixed_joint_lump__top_right_foot_visual_1">
        <pose>0.016 0 -0.070000000000000007 0 0 0</pose>
        <geometry>
          <sphere>
            <radius>0.0080000000000000002</radius>
          </sphere>
        </geometry>
        <material>
          <diffuse>0.37500003 0.37500003 0.37500003 1</diffuse>
          <ambient>0.37500003 0.37500003 0.37500003 1</ambient>
        </material>
      </visual>
    </link>
    <plugin filename="libgz_ros2_control-system.so" name="gz_ros2_control::GazeboSimROS2ControlPlugin">
      <parameters>/home/thurdparty/Code/hexapod-ros/install/hexapod_sim/share/hexapod_sim/config/hexapod_controllers.yml</parameters>
      <ros>
        <namespace>hexapod</namespace>
      </ros>
      <ros2_control name="FakeSystem" type="system">
        <hardware>
          <plugin>gz_ros2_control/GazeboSimSystem</plugin>
        </hardware>
        <joint name="top_left_rotate_joint">
          <command_interface name="position">
            <param name="min">-1.5</param>
            <param name="max">1.5</param>
          </command_interface>
          <state_interface name="position"></state_interface>
        </joint>
        <joint name="top_left_abduct_joint">
          <command_interface name="position">
            <param name="min">-1.5</param>
            <param name="max">1.5</param>
          </command_interface>
          <state_interface name="position"></state_interface>
        </joint>
        <joint name="top_left_retract_joint">
          <command_interface name="position">
            <param name="min">-1.5</param>
            <param name="max">1.5</param>
          </command_interface>
          <state_interface name="position"></state_interface>
        </joint>
        <joint name="mid_left_rotate_joint">
          <command_interface name="position">
            <param name="min">-1.5</param>
            <param name="max">1.5</param>
          </command_interface>
          <state_interface name="position"></state_interface>
        </joint>
        <joint name="mid_left_abduct_joint">
          <command_interface name="position">
            <param name="min">-1.5</param>
            <param name="max">1.5</param>
          </command_interface>
          <state_interface name="position"></state_interface>
        </joint>
        <joint name="mid_left_retract_joint">
          <command_interface name="position">
            <param name="min">-1.5</param>
            <param name="max">1.5</param>
          </command_interface>
          <state_interface name="position"></state_interface>
        </joint>
        <joint name="bottom_left_rotate_joint">
          <command_interface name="position">
            <param name="min">-1.5</param>
            <param name="max">1.5</param>
          </command_interface>
          <state_interface name="position"></state_interface>
        </joint>
        <joint name="bottom_left_abduct_joint">
          <command_interface name="position">
            <param name="min">-1.5</param>
            <param name="max">1.5</param>
          </command_interface>
          <state_interface name="position"></state_interface>
        </joint>
        <joint name="bottom_left_retract_joint">
          <command_interface name="position">
            <param name="min">-1.5</param>
            <param name="max">1.5</param>
          </command_interface>
          <state_interface name="position"></state_interface>
        </joint>
        <joint name="top_right_rotate_joint">
          <command_interface name="position">
            <param name="min">-1.5</param>
            <param name="max">1.5</param>
          </command_interface>
          <state_interface name="position"></state_interface>
        </joint>
        <joint name="top_right_abduct_joint">
          <command_interface name="position">
            <param name="min">-1.5</param>
            <param name="max">1.5</param>
          </command_interface>
          <state_interface name="position"></state_interface>
        </joint>
        <joint name="top_right_retract_joint">
          <command_interface name="position">
            <param name="min">-1.5</param>
            <param name="max">1.5</param>
          </command_interface>
          <state_interface name="position"></state_interface>
        </joint>
        <joint name="mid_right_rotate_joint">
          <command_interface name="position">
            <param name="min">-1.5</param>
            <param name="max">1.5</param>
          </command_interface>
          <state_interface name="position"></state_interface>
        </joint>
        <joint name="mid_right_abduct_joint">
          <command_interface name="position">
            <param name="min">-1.5</param>
            <param name="max">1.5</param>
          </command_interface>
          <state_interface name="position"></state_interface>
        </joint>
        <joint name="mid_right_retract_joint">
          <command_interface name="position">
            <param name="min">-1.5</param>
            <param name="max">1.5</param>
          </command_interface>
          <state_interface name="position"></state_interface>
        </joint>
        <joint name="bottom_right_rotate_joint">
          <command_interface name="position">
            <param name="min">-1.5</param>
            <param name="max">1.5</param>
          </command_interface>
          <state_interface name="position"></state_interface>
        </joint>
        <joint name="bottom_right_abduct_joint">
          <command_interface name="position">
            <param name="min">-1.5</param>
            <param name="max">1.5</param>
          </command_interface>
          <state_interface name="position"></state_interface>
        </joint>
        <joint name="bottom_right_retract_joint">
          <command_interface name="position">
            <param name="min">-1.5</param>
            <param name="max">1.5</param>
          </command_interface>
          <state_interface name="position"></state_interface>
        </joint>
      </ros2_control>
    </plugin>
    <!-- <plugin filename="libgz_ros2_control-system" name="gz_ros2_control::GazeboSimROS2ControlPlugin"> -->
    <!--   <parameters>/home/thurdparty/Code/hexapod-ros/install/hexapod_sim/share/hexapod_sim/config/hexapod_controllers.yaml</parameters> -->
    <!-- </plugin> -->
    <!-- <plugin filename="gz-sim-sensors-system" name="gz::sim::systems::Sensors"> -->
    <!--   <render_engine>ogre2</render_engine> -->
    <!-- </plugin> -->
    <frame attached_to="base_footprint" name="base_link_joint">
      <pose>0 0 0.085000000000000006 0 0 0</pose>
    </frame>
    <frame attached_to="base_link_joint" name="base_link">
      <pose>0 0 0 0 0 0</pose>
    </frame>
    <frame attached_to="bottom_left_tibia" name="bottom_left_foot_joint">
      <pose>0.016 0 -0.070000000000000007 0 0 0</pose>
    </frame>
    <frame attached_to="bottom_left_foot_joint" name="bottom_left_foot">
      <pose>0 0 0 0 0 0</pose>
    </frame>
    <frame attached_to="bottom_right_tibia" name="bottom_right_foot_joint">
      <pose>0.016 0 -0.070000000000000007 0 0 0</pose>
    </frame>
    <frame attached_to="bottom_right_foot_joint" name="bottom_right_foot">
      <pose>0 0 0 0 0 0</pose>
    </frame>
    <frame attached_to="mid_left_tibia" name="mid_left_foot_joint">
      <pose>0.016 0 -0.070000000000000007 0 0 0</pose>
    </frame>
    <frame attached_to="mid_left_foot_joint" name="mid_left_foot">
      <pose>0 0 0 0 0 0</pose>
    </frame>
    <frame attached_to="mid_right_tibia" name="mid_right_foot_joint">
      <pose>0.016 0 -0.070000000000000007 0 0 0</pose>
    </frame>
    <frame attached_to="mid_right_foot_joint" name="mid_right_foot">
      <pose>0 0 0 0 0 0</pose>
    </frame>
    <frame attached_to="top_left_tibia" name="top_left_foot_joint">
      <pose>0.016 0 -0.070000000000000007 0 0 0</pose>
    </frame>
    <frame attached_to="top_left_foot_joint" name="top_left_foot">
      <pose>0 0 0 0 0 0</pose>
    </frame>
    <frame attached_to="top_right_tibia" name="top_right_foot_joint">
      <pose>0.016 0 -0.070000000000000007 0 0 0</pose>
    </frame>
    <frame attached_to="top_right_foot_joint" name="top_right_foot">
      <pose>0 0 0 0 0 0</pose>
    </frame>
  </model>
</sdf>
