<?xml version="1.0" encoding="UTF-8"?>
<sdf version="1.11">
  <model name="hexapod">
    <link name="base_footprint">
      <inertial>
        <pose>0.0072338805980314202 0.00029300795592339417 0.1063571176134674 0 0 0</pose>
        <mass>0.1876934749386043</mass>
        <inertia>
          <ixx>0.00028623073259953719</ixx>
          <ixy>3.898652218530128e-06</ixy>
          <ixz>-1.308367059210216e-05</ixz>
          <iyy>0.00043523929657227799</iyy>
          <iyz>-1.5289347113549179e-07</iyz>
          <izz>0.0006100111286593535</izz>
        </inertia>
      </inertial>
      <collision name="base_footprint_fixed_joint_lump__base_link_collision">
        <pose>0 0 0.085000000000000006 0 0 0</pose>
        <geometry>
          <mesh>
            <scale>0.001 0.001 0.001</scale>
            <uri>file:///home/thurdparty/Code/hexapod-ros/install/hexapod_description/share/hexapod_description/meshes/collision/base_link.stl</uri>
          </mesh>
        </geometry>
        <surface>
          <contact>
            <ode></ode>
          </contact>
          <friction>
            <ode>
              <mu>0.050000000000000003</mu>
              <mu2>0.050000000000000003</mu2>
            </ode>
          </friction>
        </surface>
      </collision>
      <collision name="base_footprint_fixed_joint_lump__arm_base_collision_1">
        <pose>0 0 0.085000000000000006 0 0 0</pose>
        <geometry>
          <mesh>
            <scale>0.001 0.001 0.001</scale>
            <uri>file:///home/thurdparty/Code/hexapod-ros/install/hexapod_description/share/hexapod_description/meshes/collision/base.stl</uri>
          </mesh>
        </geometry>
      </collision>
      <visual name="base_footprint_fixed_joint_lump__base_link_visual">
        <pose>0 0 0.085000000000000006 0 0 0</pose>
        <geometry>
          <mesh>
            <scale>0.001 0.001 0.001</scale>
            <uri>file:///home/thurdparty/Code/hexapod-ros/install/hexapod_description/share/hexapod_description/meshes/visual/base_link.stl</uri>
          </mesh>
        </geometry>
        <material>
          <diffuse>0.37500003 0.37500003 0.37500003 1</diffuse>
          <ambient>0.37500003 0.37500003 0.37500003 1</ambient>
        </material>
      </visual>
      <visual name="base_footprint_fixed_joint_lump__arm_base_visual_1">
        <pose>0 0 0.085000000000000006 0 0 0</pose>
        <geometry>
          <mesh>
            <scale>0.001 0.001 0.001</scale>
            <uri>file:///home/thurdparty/Code/hexapod-ros/install/hexapod_description/share/hexapod_description/meshes/visual/base.stl</uri>
          </mesh>
        </geometry>
        <material>
          <diffuse>0.37500003 0.37500003 0.37500003 1</diffuse>
          <ambient>0.37500003 0.37500003 0.37500003 1</ambient>
        </material>
      </visual>
      <self_collide>false</self_collide>
    </link>
    <joint name="arm_rotator_joint" type="revolute">
      <pose relative_to="base_footprint">0.025676000000000001 0.00057600000000000012 0.15984999999999999 0 0 0</pose>
      <parent>base_footprint</parent>
      <child>arm_rotator</child>
      <axis>
        <xyz>0 0 -1</xyz>
        <limit>
          <effort>100</effort>
          <velocity>100</velocity>
          <lower>-inf</lower>
          <upper>inf</upper>
        </limit>
        <dynamics>
          <spring_reference>0</spring_reference>
          <spring_stiffness>0</spring_stiffness>
        </dynamics>
      </axis>
    </joint>
    <link name="arm_rotator">
      <pose relative_to="arm_rotator_joint">0 0 0 0 0 0</pose>
      <inertial>
        <pose>-0.00046642883527773718 0.0027188082250819241 0.00576546998065737 0 0 0</pose>
        <mass>0.026235460257998749</mass>
        <inertia>
          <ixx>3.9999999999999998e-06</ixx>
          <ixy>0</ixy>
          <ixz>0</ixz>
          <iyy>3.9999999999999998e-06</iyy>
          <iyz>0</iyz>
          <izz>5.0000000000000004e-06</izz>
        </inertia>
      </inertial>
      <collision name="arm_rotator_collision">
        <pose>-0.025676000000000001 -0.00057600000000000001 -0.07485 0 0 0</pose>
        <geometry>
          <mesh>
            <scale>0.001 0.001 0.001</scale>
            <uri>file:///home/thurdparty/Code/hexapod-ros/install/hexapod_description/share/hexapod_description/meshes/collision/rotator.stl</uri>
          </mesh>
        </geometry>
      </collision>
      <visual name="arm_rotator_visual">
        <pose>-0.025676000000000001 -0.00057600000000000001 -0.07485 0 0 0</pose>
        <geometry>
          <mesh>
            <scale>0.001 0.001 0.001</scale>
            <uri>file:///home/thurdparty/Code/hexapod-ros/install/hexapod_description/share/hexapod_description/meshes/visual/rotator.stl</uri>
          </mesh>
        </geometry>
        <material>
          <diffuse>0.37500003 0.37500003 0.37500003 1</diffuse>
          <ambient>0.37500003 0.37500003 0.37500003 1</ambient>
        </material>
      </visual>
    </link>
    <joint name="arm_abductor_joint" type="revolute">
      <pose relative_to="arm_rotator">0.014581999999999999 0.00068999999999999997 0.013923 0 0 0</pose>
      <parent>arm_rotator</parent>
      <child>arm_abductor</child>
      <axis>
        <xyz>-1 0 0</xyz>
        <limit>
          <lower>-1.5707960000000001</lower>
          <upper>1.5707960000000001</upper>
          <effort>100</effort>
          <velocity>100</velocity>
        </limit>
        <dynamics>
          <spring_reference>0</spring_reference>
          <spring_stiffness>0</spring_stiffness>
        </dynamics>
      </axis>
    </joint>
    <link name="arm_abductor">
      <pose relative_to="arm_abductor_joint">0 0 0 0 0 0</pose>
      <inertial>
        <pose>-0.014167725035919119 3.5639852713031771e-07 0.031090662760010459 0 0 0</pose>
        <mass>0.016534189067873271</mass>
        <inertia>
          <ixx>5.0000000000000004e-06</ixx>
          <ixy>0</ixy>
          <ixz>9.9999999999999995e-07</ixz>
          <iyy>6.9999999999999999e-06</iyy>
          <iyz>0</iyz>
          <izz>1.9999999999999999e-06</izz>
        </inertia>
      </inertial>
      <collision name="arm_abductor_collision">
        <pose>-0.040258000000000002 -0.001266 -0.088773000000000005 0 0 0</pose>
        <geometry>
          <mesh>
            <scale>0.001 0.001 0.001</scale>
            <uri>file:///home/thurdparty/Code/hexapod-ros/install/hexapod_description/share/hexapod_description/meshes/collision/abductor.stl</uri>
          </mesh>
        </geometry>
      </collision>
      <visual name="arm_abductor_visual">
        <pose>-0.040258000000000002 -0.001266 -0.088773000000000005 0 0 0</pose>
        <geometry>
          <mesh>
            <scale>0.001 0.001 0.001</scale>
            <uri>file:///home/thurdparty/Code/hexapod-ros/install/hexapod_description/share/hexapod_description/meshes/visual/abductor.stl</uri>
          </mesh>
        </geometry>
        <material>
          <diffuse>0.37500003 0.37500003 0.37500003 1</diffuse>
          <ambient>0.37500003 0.37500003 0.37500003 1</ambient>
        </material>
      </visual>
    </link>
    <joint name="arm_retractor_joint" type="revolute">
      <pose relative_to="arm_abductor">-0.00040099999999999999 0 0.046709000000000001 0 0 0</pose>
      <parent>arm_abductor</parent>
      <child>arm_retractor</child>
      <axis>
        <xyz>-0.99999300000000002 0 -0.003676</xyz>
        <limit>
          <lower>-1.5707960000000001</lower>
          <upper>1.5707960000000001</upper>
          <effort>100</effort>
          <velocity>100</velocity>
        </limit>
        <dynamics>
          <spring_reference>0</spring_reference>
          <spring_stiffness>0</spring_stiffness>
        </dynamics>
      </axis>
    </joint>
    <link name="arm_retractor">
      <pose relative_to="arm_retractor_joint">0 0 0 0 0 0</pose>
      <inertial>
        <pose>-0.004404397432206335 0.028800148655828622 0.055147099289247839 0 0 0</pose>
        <mass>0.022054446872393021</mass>
        <inertia>
          <ixx>9.7604469514316704e-05</ixx>
          <ixy>-9.603467881046577e-06</ixy>
          <ixz>-1.0578923179550571e-05</ixz>
          <iyy>6.0971994445165682e-05</iyy>
          <iyz>-4.6086416521681348e-05</iyz>
          <izz>4.9041338098155538e-05</izz>
        </inertia>
      </inertial>
      <collision name="arm_retractor_collision">
        <pose>-0.039856999999999997 -0.001266 -0.13548199999999999 0 0 0</pose>
        <geometry>
          <mesh>
            <scale>0.001 0.001 0.001</scale>
            <uri>file:///home/thurdparty/Code/hexapod-ros/install/hexapod_description/share/hexapod_description/meshes/collision/retractor.stl</uri>
          </mesh>
        </geometry>
      </collision>
      <collision name="arm_retractor_fixed_joint_lump__camera_case_cover_collision_1">
        <pose>0.0079840000000000293 -0.080935000000000007 0.096998999999999974 -1.5707963267948957 -1.5707963267948966 0</pose>
        <geometry>
          <mesh>
            <scale>0.001 0.001 0.001</scale>
            <uri>file:///home/thurdparty/Code/hexapod-ros/install/hexapod_description/share/hexapod_description/meshes/collision/camera_case_cover.stl</uri>
          </mesh>
        </geometry>
      </collision>
      <visual name="arm_retractor_visual">
        <pose>-0.039856999999999997 -0.001266 -0.13548199999999999 0 0 0</pose>
        <geometry>
          <mesh>
            <scale>0.001 0.001 0.001</scale>
            <uri>file:///home/thurdparty/Code/hexapod-ros/install/hexapod_description/share/hexapod_description/meshes/visual/retractor.stl</uri>
          </mesh>
        </geometry>
        <material>
          <diffuse>0.37500003 0.37500003 0.37500003 1</diffuse>
          <ambient>0.37500003 0.37500003 0.37500003 1</ambient>
        </material>
      </visual>
      <visual name="arm_retractor_fixed_joint_lump__camera_case_cover_visual_1">
        <pose>-0.039999999999999987 2.775557561562891e-17 -0.13 -2.4651903288156619e-32 -2.2204460492503131e-16 2.2204460492503131e-16</pose>
        <geometry>
          <mesh>
            <scale>0.001 0.001 0.001</scale>
            <uri>file:///home/thurdparty/Code/hexapod-ros/install/hexapod_description/share/hexapod_description/meshes/visual/camera_case_cover.stl</uri>
          </mesh>
        </geometry>
        <material>
          <diffuse>0.37500003 0.37500003 0.37500003 1</diffuse>
          <ambient>0.37500003 0.37500003 0.37500003 1</ambient>
        </material>
      </visual>
      <visual name="arm_retractor_fixed_joint_lump__depth_camera_link_visual_2">
        <pose>-0.01 5.2041704279304213e-18 0.042500000000000003 -1.5707963267948957 -1.5707963267948966 0</pose>
        <geometry>
          <box>
            <size>0.01 0.040000000000000001 0.029999999999999999</size>
          </box>
        </geometry>
      </visual>
      <sensor name="depth_camera_link" type="depth_camera">
        <always_on>true</always_on>
        <visualize>true</visualize>
        <update_rate>100</update_rate>
        <topic>depth_camera/depth/image_raw</topic>
        <camera name="Sipeed_MaixSense_A010">
          <camera_info_topic>depth_camera/depth/camera_info</camera_info_topic>
          <horizontal_fov>1.0471999999999999</horizontal_fov>
          <image>
            <width>100</width>
            <height>100</height>
            <format>R_FLOAT32</format>
          </image>
          <clip>
            <near>0.050000000000000003</near>
            <far>3</far>
          </clip>
          <noise>
            <type>gaussian</type>
            <mean>0</mean>
            <stddev>0.01</stddev>
          </noise>
        </camera>
        <pose>-0.012500000000000001 0 0.055 3.1415926535746808 -1.5707926535453185 1.570792653591518</pose>
        <gz_frame_id>depth_camera_optical_frame</gz_frame_id>
      </sensor>
    </link>
    <joint name="bottom_left_rotate_joint" type="revolute">
      <pose relative_to="base_footprint">-0.067095000000000002 0.047400999999999999 0.1147 0 0 0.78539816339744839</pose>
      <parent>base_footprint</parent>
      <child>bottom_left_cox</child>
      <axis>
        <xyz>0 0 -1</xyz>
        <limit>
          <lower>-1.5707960000000001</lower>
          <upper>1.5707960000000001</upper>
          <effort>100</effort>
          <velocity>100</velocity>
        </limit>
        <dynamics>
          <spring_reference>0</spring_reference>
          <spring_stiffness>0</spring_stiffness>
        </dynamics>
      </axis>
    </joint>
    <link name="bottom_left_cox">
      <pose relative_to="bottom_left_rotate_joint">0 0 0 0 0 0</pose>
      <inertial>
        <pose>0.0012733261090569091 0.014903434394979129 -0.020345821820411621 0 0 0</pose>
        <mass>0.01391683496290758</mass>
        <inertia>
          <ixx>3.0000000000000001e-06</ixx>
          <ixy>0</ixy>
          <ixz>0</ixz>
          <iyy>3.9999999999999998e-06</iyy>
          <iyz>0</iyz>
          <izz>3.0000000000000001e-06</izz>
        </inertia>
      </inertial>
      <collision name="bottom_left_cox_collision">
        <pose>-0.0036120000000000002 -0.056729000000000002 -0.030599999999999999 0 0 0</pose>
        <geometry>
          <mesh>
            <scale>0.001 0.001 0.001</scale>
            <uri>file:///home/thurdparty/Code/hexapod-ros/install/hexapod_description/share/hexapod_description/meshes/collision/cox_left.stl</uri>
          </mesh>
        </geometry>
      </collision>
      <visual name="bottom_left_cox_visual">
        <pose>-0.0036120000000000002 -0.056729000000000002 -0.030599999999999999 0 0 0</pose>
        <geometry>
          <mesh>
            <scale>0.001 0.001 0.001</scale>
            <uri>file:///home/thurdparty/Code/hexapod-ros/install/hexapod_description/share/hexapod_description/meshes/visual/cox_left.stl</uri>
          </mesh>
        </geometry>
        <material>
          <diffuse>0.37500003 0.37500003 0.37500003 1</diffuse>
          <ambient>0.37500003 0.37500003 0.37500003 1</ambient>
        </material>
      </visual>
    </link>
    <joint name="bottom_left_abduct_joint" type="revolute">
      <pose relative_to="bottom_left_cox">0.020937000000000001 0.029999999999999999 -0.021804 0 0 0</pose>
      <parent>bottom_left_cox</parent>
      <child>bottom_left_femur</child>
      <axis>
        <xyz>-1 0 0</xyz>
        <limit>
          <lower>-1.5707960000000001</lower>
          <upper>1.5707960000000001</upper>
          <effort>100</effort>
          <velocity>100</velocity>
        </limit>
        <dynamics>
          <spring_reference>0</spring_reference>
          <spring_stiffness>0</spring_stiffness>
        </dynamics>
      </axis>
    </joint>
    <link name="bottom_left_femur">
      <pose relative_to="bottom_left_abduct_joint">0 0 0 0 0 0</pose>
      <inertial>
        <pose>-0.01501165493471714 0.020989624323966821 -0.0057282527349048016 0 0 0</pose>
        <mass>0.01882378454979923</mass>
        <inertia>
          <ixx>5.0000000000000004e-06</ixx>
          <ixy>0</ixy>
          <ixz>0</ixz>
          <iyy>3.0000000000000001e-06</iyy>
          <iyz>1.9999999999999999e-06</iyz>
          <izz>5.0000000000000004e-06</izz>
        </inertia>
      </inertial>
      <collision name="bottom_left_femur_collision">
        <pose>-0.024549000000000001 -0.086729000000000001 -0.008796 0 0 0</pose>
        <geometry>
          <mesh>
            <scale>0.001 0.001 0.001</scale>
            <uri>file:///home/thurdparty/Code/hexapod-ros/install/hexapod_description/share/hexapod_description/meshes/collision/femur_left.stl</uri>
          </mesh>
        </geometry>
      </collision>
      <visual name="bottom_left_femur_visual">
        <pose>-0.024549000000000001 -0.086729000000000001 -0.008796 0 0 0</pose>
        <geometry>
          <mesh>
            <scale>0.001 0.001 0.001</scale>
            <uri>file:///home/thurdparty/Code/hexapod-ros/install/hexapod_description/share/hexapod_description/meshes/visual/femur_left.stl</uri>
          </mesh>
        </geometry>
        <material>
          <diffuse>0.37500003 0.37500003 0.37500003 1</diffuse>
          <ambient>0.37500003 0.37500003 0.37500003 1</ambient>
        </material>
      </visual>
    </link>
    <joint name="bottom_left_retract_joint" type="revolute">
      <pose relative_to="bottom_left_femur">-0.029923000000000002 0.039696000000000002 -0.018563 0 0 0</pose>
      <parent>bottom_left_femur</parent>
      <child>bottom_left_tibia</child>
      <axis>
        <xyz>1 0.00011 0</xyz>
        <limit>
          <lower>-1.5707960000000001</lower>
          <upper>1.5707960000000001</upper>
          <effort>100</effort>
          <velocity>100</velocity>
        </limit>
        <dynamics>
          <spring_reference>0</spring_reference>
          <spring_stiffness>0</spring_stiffness>
        </dynamics>
      </axis>
    </joint>
    <link name="bottom_left_tibia">
      <pose relative_to="bottom_left_retract_joint">0 0 0 0 0 0</pose>
      <inertial>
        <pose>0.015773574057860749 0.0058949324510389556 -0.043764578888882869 0 0 0</pose>
        <mass>0.02227943835487755</mass>
        <inertia>
          <ixx>1.939875416507577e-05</ixx>
          <ixy>2.4217580481392058e-08</ixy>
          <ixz>1.0778044150611289e-07</ixz>
          <iyy>1.9769186821995458e-05</iyy>
          <iyz>-3.8060319246942551e-06</iyz>
          <izz>3.9114277506498263e-06</izz>
        </inertia>
      </inertial>
      <collision name="bottom_left_tibia_collision">
        <pose>0.0053740000000000003 -0.12642500000000001 0.0097669999999999996 0 0 0</pose>
        <geometry>
          <mesh>
            <scale>0.001 0.001 0.001</scale>
            <uri>file:///home/thurdparty/Code/hexapod-ros/install/hexapod_description/share/hexapod_description/meshes/collision/tibia_left.stl</uri>
          </mesh>
        </geometry>
      </collision>
      <collision name="bottom_left_tibia_fixed_joint_lump__foot_collision_collision_1">
        <pose>0.016 0 -0.070000000000000007 0 0 0</pose>
        <geometry>
          <sphere>
            <radius>0.0080000000000000002</radius>
          </sphere>
        </geometry>
      </collision>
      <visual name="bottom_left_tibia_visual">
        <pose>0.0053740000000000003 -0.12642500000000001 0.0097669999999999996 0 0 0</pose>
        <geometry>
          <mesh>
            <scale>0.001 0.001 0.001</scale>
            <uri>file:///home/thurdparty/Code/hexapod-ros/install/hexapod_description/share/hexapod_description/meshes/visual/tibia_left.stl</uri>
          </mesh>
        </geometry>
        <material>
          <diffuse>0.37500003 0.37500003 0.37500003 1</diffuse>
          <ambient>0.37500003 0.37500003 0.37500003 1</ambient>
        </material>
      </visual>
      <visual name="bottom_left_tibia_fixed_joint_lump__bottom_left_foot_visual_1">
        <pose>0.016 0 -0.070000000000000007 0 0 0</pose>
        <geometry>
          <sphere>
            <radius>0.0080000000000000002</radius>
          </sphere>
        </geometry>
        <material>
          <diffuse>0.37500003 0.37500003 0.37500003 1</diffuse>
          <ambient>0.37500003 0.37500003 0.37500003 1</ambient>
        </material>
      </visual>
    </link>
    <joint name="bottom_right_rotate_joint" type="revolute">
      <pose relative_to="base_footprint">-0.067095000000000002 -0.046740999999999998 0.1147 0 0 2.3561944901923448</pose>
      <parent>base_footprint</parent>
      <child>bottom_right_cox</child>
      <axis>
        <xyz>0 0 -1</xyz>
        <limit>
          <lower>-1.5707960000000001</lower>
          <upper>1.5707960000000001</upper>
          <effort>100</effort>
          <velocity>100</velocity>
        </limit>
        <dynamics>
          <spring_reference>0</spring_reference>
          <spring_stiffness>0</spring_stiffness>
        </dynamics>
      </axis>
    </joint>
    <link name="bottom_right_cox">
      <pose relative_to="bottom_right_rotate_joint">0 0 0 0 0 0</pose>
      <inertial>
        <pose>0.0012733261090569091 0.014903434394979129 -0.020345821820411621 0 0 0</pose>
        <mass>0.01391683496290758</mass>
        <inertia>
          <ixx>3.0000000000000001e-06</ixx>
          <ixy>0</ixy>
          <ixz>0</ixz>
          <iyy>3.9999999999999998e-06</iyy>
          <iyz>0</iyz>
          <izz>3.0000000000000001e-06</izz>
        </inertia>
      </inertial>
      <collision name="bottom_right_cox_collision">
        <pose>0.0035000000000000001 -0.055 -0.030599999999999999 0 0 3.1415926535897931</pose>
        <geometry>
          <mesh>
            <scale>0.001 0.001 0.001</scale>
            <uri>file:///home/thurdparty/Code/hexapod-ros/install/hexapod_description/share/hexapod_description/meshes/collision/cox_right.stl</uri>
          </mesh>
        </geometry>
      </collision>
      <visual name="bottom_right_cox_visual">
        <pose>0.0035000000000000001 -0.055 -0.030599999999999999 0 0 3.1415926535897931</pose>
        <geometry>
          <mesh>
            <scale>0.001 0.001 0.001</scale>
            <uri>file:///home/thurdparty/Code/hexapod-ros/install/hexapod_description/share/hexapod_description/meshes/visual/cox_right.stl</uri>
          </mesh>
        </geometry>
        <material>
          <diffuse>0.37500003 0.37500003 0.37500003 1</diffuse>
          <ambient>0.37500003 0.37500003 0.37500003 1</ambient>
        </material>
      </visual>
    </link>
    <joint name="bottom_right_abduct_joint" type="revolute">
      <pose relative_to="bottom_right_cox">0.0077499999999999999 0.029999999999999999 -0.021804 0 0 0</pose>
      <parent>bottom_right_cox</parent>
      <child>bottom_right_femur</child>
      <axis>
        <xyz>-1 0 0</xyz>
        <limit>
          <lower>-1.5707960000000001</lower>
          <upper>1.5707960000000001</upper>
          <effort>100</effort>
          <velocity>100</velocity>
        </limit>
        <dynamics>
          <spring_reference>0</spring_reference>
          <spring_stiffness>0</spring_stiffness>
        </dynamics>
      </axis>
    </joint>
    <link name="bottom_right_femur">
      <pose relative_to="bottom_right_abduct_joint">0 0 0 0 0 0</pose>
      <inertial>
        <pose>-0.01501165493471714 0.020989624323966821 -0.0057282527349048016 0 0 0</pose>
        <mass>0.01882378454979923</mass>
        <inertia>
          <ixx>5.0000000000000004e-06</ixx>
          <ixy>0</ixy>
          <ixz>0</ixz>
          <iyy>3.0000000000000001e-06</iyy>
          <iyz>1.9999999999999999e-06</iyz>
          <izz>5.0000000000000004e-06</izz>
        </inertia>
      </inertial>
      <collision name="bottom_right_femur_collision">
        <pose>-0.0035000000000000001 -0.085000000000000006 -0.0085000000000000006 0 0 3.1415926535897931</pose>
        <geometry>
          <mesh>
            <scale>0.001 0.001 0.001</scale>
            <uri>file:///home/thurdparty/Code/hexapod-ros/install/hexapod_description/share/hexapod_description/meshes/collision/femur_right.stl</uri>
          </mesh>
        </geometry>
      </collision>
      <visual name="bottom_right_femur_visual">
        <pose>-0.0035000000000000001 -0.085000000000000006 -0.0085000000000000006 0 0 3.1415926535897931</pose>
        <geometry>
          <mesh>
            <scale>0.001 0.001 0.001</scale>
            <uri>file:///home/thurdparty/Code/hexapod-ros/install/hexapod_description/share/hexapod_description/meshes/visual/femur_right.stl</uri>
          </mesh>
        </geometry>
        <material>
          <diffuse>0.37500003 0.37500003 0.37500003 1</diffuse>
          <ambient>0.37500003 0.37500003 0.37500003 1</ambient>
        </material>
      </visual>
    </link>
    <joint name="bottom_right_retract_joint" type="revolute">
      <pose relative_to="bottom_right_femur">-0.029923000000000002 0.039696000000000002 -0.018563 0 0 0</pose>
      <parent>bottom_right_femur</parent>
      <child>bottom_right_tibia</child>
      <axis>
        <xyz>1 0.00011 0</xyz>
        <limit>
          <lower>-1.5707960000000001</lower>
          <upper>1.5707960000000001</upper>
          <effort>100</effort>
          <velocity>100</velocity>
        </limit>
        <dynamics>
          <spring_reference>0</spring_reference>
          <spring_stiffness>0</spring_stiffness>
        </dynamics>
      </axis>
    </joint>
    <link name="bottom_right_tibia">
      <pose relative_to="bottom_right_retract_joint">0 0 0 0 0 0</pose>
      <inertial>
        <pose>0.015773574057860749 0.0058949324510389556 -0.043764578888882869 0 0 0</pose>
        <mass>0.02227943835487755</mass>
        <inertia>
          <ixx>1.939875416507577e-05</ixx>
          <ixy>2.4217580481392058e-08</ixy>
          <ixz>1.0778044150611289e-07</ixz>
          <iyy>1.9769186821995458e-05</iyy>
          <iyz>-3.8060319246942551e-06</iyz>
          <izz>3.9114277506498263e-06</izz>
        </inertia>
      </inertial>
      <collision name="bottom_right_tibia_collision">
        <pose>0.0275 -0.125 0.01 0 0 3.1415926535897931</pose>
        <geometry>
          <mesh>
            <scale>0.001 0.001 0.001</scale>
            <uri>file:///home/thurdparty/Code/hexapod-ros/install/hexapod_description/share/hexapod_description/meshes/collision/tibia_right.stl</uri>
          </mesh>
        </geometry>
      </collision>
      <collision name="bottom_right_tibia_fixed_joint_lump__foot_collision_collision_1">
        <pose>0.016 0 -0.070000000000000007 0 0 0</pose>
        <geometry>
          <sphere>
            <radius>0.0080000000000000002</radius>
          </sphere>
        </geometry>
      </collision>
      <visual name="bottom_right_tibia_visual">
        <pose>0.0275 -0.125 0.01 0 0 3.1415926535897931</pose>
        <geometry>
          <mesh>
            <scale>0.001 0.001 0.001</scale>
            <uri>file:///home/thurdparty/Code/hexapod-ros/install/hexapod_description/share/hexapod_description/meshes/visual/tibia_right.stl</uri>
          </mesh>
        </geometry>
        <material>
          <diffuse>0.37500003 0.37500003 0.37500003 1</diffuse>
          <ambient>0.37500003 0.37500003 0.37500003 1</ambient>
        </material>
      </visual>
      <visual name="bottom_right_tibia_fixed_joint_lump__bottom_right_foot_visual_1">
        <pose>0.016 0 -0.070000000000000007 0 0 0</pose>
        <geometry>
          <sphere>
            <radius>0.0080000000000000002</radius>
          </sphere>
        </geometry>
        <material>
          <diffuse>0.37500003 0.37500003 0.37500003 1</diffuse>
          <ambient>0.37500003 0.37500003 0.37500003 1</ambient>
        </material>
      </visual>
    </link>
    <joint name="mid_left_rotate_joint" type="revolute">
      <pose relative_to="base_footprint">0.0036120000000000002 0.056729000000000002 0.11559999999999999 0 0 0</pose>
      <parent>base_footprint</parent>
      <child>mid_left_cox</child>
      <axis>
        <xyz>0 0 -1</xyz>
        <limit>
          <lower>-1.5707960000000001</lower>
          <upper>1.5707960000000001</upper>
          <effort>100</effort>
          <velocity>100</velocity>
        </limit>
        <dynamics>
          <spring_reference>0</spring_reference>
          <spring_stiffness>0</spring_stiffness>
        </dynamics>
      </axis>
    </joint>
    <link name="mid_left_cox">
      <pose relative_to="mid_left_rotate_joint">0 0 0 0 0 0</pose>
      <inertial>
        <pose>0.0012733261090569091 0.014903434394979129 -0.020345821820411621 0 0 0</pose>
        <mass>0.01391683496290758</mass>
        <inertia>
          <ixx>3.0000000000000001e-06</ixx>
          <ixy>0</ixy>
          <ixz>0</ixz>
          <iyy>3.9999999999999998e-06</iyy>
          <iyz>0</iyz>
          <izz>3.0000000000000001e-06</izz>
        </inertia>
      </inertial>
      <collision name="mid_left_cox_collision">
        <pose>-0.0036120000000000002 -0.056729000000000002 -0.030599999999999999 0 0 0</pose>
        <geometry>
          <mesh>
            <scale>0.001 0.001 0.001</scale>
            <uri>file:///home/thurdparty/Code/hexapod-ros/install/hexapod_description/share/hexapod_description/meshes/collision/cox_left.stl</uri>
          </mesh>
        </geometry>
      </collision>
      <visual name="mid_left_cox_visual">
        <pose>-0.0036120000000000002 -0.056729000000000002 -0.030599999999999999 0 0 0</pose>
        <geometry>
          <mesh>
            <scale>0.001 0.001 0.001</scale>
            <uri>file:///home/thurdparty/Code/hexapod-ros/install/hexapod_description/share/hexapod_description/meshes/visual/cox_left.stl</uri>
          </mesh>
        </geometry>
        <material>
          <diffuse>0.37500003 0.37500003 0.37500003 1</diffuse>
          <ambient>0.37500003 0.37500003 0.37500003 1</ambient>
        </material>
      </visual>
    </link>
    <joint name="mid_left_abduct_joint" type="revolute">
      <pose relative_to="mid_left_cox">0.020937000000000001 0.029999999999999999 -0.021804 0 0 0</pose>
      <parent>mid_left_cox</parent>
      <child>mid_left_femur</child>
      <axis>
        <xyz>-1 0 0</xyz>
        <limit>
          <lower>-1.5707960000000001</lower>
          <upper>1.5707960000000001</upper>
          <effort>100</effort>
          <velocity>100</velocity>
        </limit>
        <dynamics>
          <spring_reference>0</spring_reference>
          <spring_stiffness>0</spring_stiffness>
        </dynamics>
      </axis>
    </joint>
    <link name="mid_left_femur">
      <pose relative_to="mid_left_abduct_joint">0 0 0 0 0 0</pose>
      <inertial>
        <pose>-0.01501165493471714 0.020989624323966821 -0.0057282527349048016 0 0 0</pose>
        <mass>0.01882378454979923</mass>
        <inertia>
          <ixx>5.0000000000000004e-06</ixx>
          <ixy>0</ixy>
          <ixz>0</ixz>
          <iyy>3.0000000000000001e-06</iyy>
          <iyz>1.9999999999999999e-06</iyz>
          <izz>5.0000000000000004e-06</izz>
        </inertia>
      </inertial>
      <collision name="mid_left_femur_collision">
        <pose>-0.024549000000000001 -0.086729000000000001 -0.008796 0 0 0</pose>
        <geometry>
          <mesh>
            <scale>0.001 0.001 0.001</scale>
            <uri>file:///home/thurdparty/Code/hexapod-ros/install/hexapod_description/share/hexapod_description/meshes/collision/femur_left.stl</uri>
          </mesh>
        </geometry>
      </collision>
      <visual name="mid_left_femur_visual">
        <pose>-0.024549000000000001 -0.086729000000000001 -0.008796 0 0 0</pose>
        <geometry>
          <mesh>
            <scale>0.001 0.001 0.001</scale>
            <uri>file:///home/thurdparty/Code/hexapod-ros/install/hexapod_description/share/hexapod_description/meshes/visual/femur_left.stl</uri>
          </mesh>
        </geometry>
        <material>
          <diffuse>0.37500003 0.37500003 0.37500003 1</diffuse>
          <ambient>0.37500003 0.37500003 0.37500003 1</ambient>
        </material>
      </visual>
    </link>
    <joint name="mid_left_retract_joint" type="revolute">
      <pose relative_to="mid_left_femur">-0.029923000000000002 0.039696000000000002 -0.018563 0 0 0</pose>
      <parent>mid_left_femur</parent>
      <child>mid_left_tibia</child>
      <axis>
        <xyz>1 0.00011 0</xyz>
        <limit>
          <lower>-1.5707960000000001</lower>
          <upper>1.5707960000000001</upper>
          <effort>100</effort>
          <velocity>100</velocity>
        </limit>
        <dynamics>
          <spring_reference>0</spring_reference>
          <spring_stiffness>0</spring_stiffness>
        </dynamics>
      </axis>
    </joint>
    <link name="mid_left_tibia">
      <pose relative_to="mid_left_retract_joint">0 0 0 0 0 0</pose>
      <inertial>
        <pose>0.015773574057860749 0.0058949324510389556 -0.043764578888882869 0 0 0</pose>
        <mass>0.02227943835487755</mass>
        <inertia>
          <ixx>1.939875416507577e-05</ixx>
          <ixy>2.4217580481392058e-08</ixy>
          <ixz>1.0778044150611289e-07</ixz>
          <iyy>1.9769186821995458e-05</iyy>
          <iyz>-3.8060319246942551e-06</iyz>
          <izz>3.9114277506498263e-06</izz>
        </inertia>
      </inertial>
      <collision name="mid_left_tibia_collision">
        <pose>0.0053740000000000003 -0.12642500000000001 0.0097669999999999996 0 0 0</pose>
        <geometry>
          <mesh>
            <scale>0.001 0.001 0.001</scale>
            <uri>file:///home/thurdparty/Code/hexapod-ros/install/hexapod_description/share/hexapod_description/meshes/collision/tibia_left.stl</uri>
          </mesh>
        </geometry>
      </collision>
      <collision name="mid_left_tibia_fixed_joint_lump__foot_collision_collision_1">
        <pose>0.016 0 -0.070000000000000007 0 0 0</pose>
        <geometry>
          <sphere>
            <radius>0.0080000000000000002</radius>
          </sphere>
        </geometry>
      </collision>
      <visual name="mid_left_tibia_visual">
        <pose>0.0053740000000000003 -0.12642500000000001 0.0097669999999999996 0 0 0</pose>
        <geometry>
          <mesh>
            <scale>0.001 0.001 0.001</scale>
            <uri>file:///home/thurdparty/Code/hexapod-ros/install/hexapod_description/share/hexapod_description/meshes/visual/tibia_left.stl</uri>
          </mesh>
        </geometry>
        <material>
          <diffuse>0.37500003 0.37500003 0.37500003 1</diffuse>
          <ambient>0.37500003 0.37500003 0.37500003 1</ambient>
        </material>
      </visual>
      <visual name="mid_left_tibia_fixed_joint_lump__mid_left_foot_visual_1">
        <pose>0.016 0 -0.070000000000000007 0 0 0</pose>
        <geometry>
          <sphere>
            <radius>0.0080000000000000002</radius>
          </sphere>
        </geometry>
        <material>
          <diffuse>0.37500003 0.37500003 0.37500003 1</diffuse>
          <ambient>0.37500003 0.37500003 0.37500003 1</ambient>
        </material>
      </visual>
    </link>
    <joint name="mid_right_rotate_joint" type="revolute">
      <pose relative_to="base_footprint">0.0035739999999999999 -0.054899000000000003 0.11559999999999999 0 0 3.1415926535897931</pose>
      <parent>base_footprint</parent>
      <child>mid_right_cox</child>
      <axis>
        <xyz>0 0 -1</xyz>
        <limit>
          <lower>-1.5707960000000001</lower>
          <upper>1.5707960000000001</upper>
          <effort>100</effort>
          <velocity>100</velocity>
        </limit>
        <dynamics>
          <spring_reference>0</spring_reference>
          <spring_stiffness>0</spring_stiffness>
        </dynamics>
      </axis>
    </joint>
    <link name="mid_right_cox">
      <pose relative_to="mid_right_rotate_joint">0 0 0 0 0 0</pose>
      <inertial>
        <pose>0.0012733261090569091 0.014903434394979129 -0.020345821820411621 0 0 0</pose>
        <mass>0.01391683496290758</mass>
        <inertia>
          <ixx>3.0000000000000001e-06</ixx>
          <ixy>0</ixy>
          <ixz>0</ixz>
          <iyy>3.9999999999999998e-06</iyy>
          <iyz>0</iyz>
          <izz>3.0000000000000001e-06</izz>
        </inertia>
      </inertial>
      <collision name="mid_right_cox_collision">
        <pose>0.0035000000000000001 -0.055 -0.030599999999999999 0 0 3.1415926535897931</pose>
        <geometry>
          <mesh>
            <scale>0.001 0.001 0.001</scale>
            <uri>file:///home/thurdparty/Code/hexapod-ros/install/hexapod_description/share/hexapod_description/meshes/collision/cox_right.stl</uri>
          </mesh>
        </geometry>
      </collision>
      <visual name="mid_right_cox_visual">
        <pose>0.0035000000000000001 -0.055 -0.030599999999999999 0 0 3.1415926535897931</pose>
        <geometry>
          <mesh>
            <scale>0.001 0.001 0.001</scale>
            <uri>file:///home/thurdparty/Code/hexapod-ros/install/hexapod_description/share/hexapod_description/meshes/visual/cox_right.stl</uri>
          </mesh>
        </geometry>
        <material>
          <diffuse>0.37500003 0.37500003 0.37500003 1</diffuse>
          <ambient>0.37500003 0.37500003 0.37500003 1</ambient>
        </material>
      </visual>
    </link>
    <joint name="mid_right_abduct_joint" type="revolute">
      <pose relative_to="mid_right_cox">0.0077499999999999999 0.029999999999999999 -0.021804 0 0 0</pose>
      <parent>mid_right_cox</parent>
      <child>mid_right_femur</child>
      <axis>
        <xyz>-1 0 0</xyz>
        <limit>
          <lower>-1.5707960000000001</lower>
          <upper>1.5707960000000001</upper>
          <effort>100</effort>
          <velocity>100</velocity>
        </limit>
        <dynamics>
          <spring_reference>0</spring_reference>
          <spring_stiffness>0</spring_stiffness>
        </dynamics>
      </axis>
    </joint>
    <link name="mid_right_femur">
      <pose relative_to="mid_right_abduct_joint">0 0 0 0 0 0</pose>
      <inertial>
        <pose>-0.01501165493471714 0.020989624323966821 -0.0057282527349048016 0 0 0</pose>
        <mass>0.01882378454979923</mass>
        <inertia>
          <ixx>5.0000000000000004e-06</ixx>
          <ixy>0</ixy>
          <ixz>0</ixz>
          <iyy>3.0000000000000001e-06</iyy>
          <iyz>1.9999999999999999e-06</iyz>
          <izz>5.0000000000000004e-06</izz>
        </inertia>
      </inertial>
      <collision name="mid_right_femur_collision">
        <pose>-0.0035000000000000001 -0.085000000000000006 -0.0085000000000000006 0 0 3.1415926535897931</pose>
        <geometry>
          <mesh>
            <scale>0.001 0.001 0.001</scale>
            <uri>file:///home/thurdparty/Code/hexapod-ros/install/hexapod_description/share/hexapod_description/meshes/collision/femur_right.stl</uri>
          </mesh>
        </geometry>
      </collision>
      <visual name="mid_right_femur_visual">
        <pose>-0.0035000000000000001 -0.085000000000000006 -0.0085000000000000006 0 0 3.1415926535897931</pose>
        <geometry>
          <mesh>
            <scale>0.001 0.001 0.001</scale>
            <uri>file:///home/thurdparty/Code/hexapod-ros/install/hexapod_description/share/hexapod_description/meshes/visual/femur_right.stl</uri>
          </mesh>
        </geometry>
        <material>
          <diffuse>0.37500003 0.37500003 0.37500003 1</diffuse>
          <ambient>0.37500003 0.37500003 0.37500003 1</ambient>
        </material>
      </visual>
    </link>
    <joint name="mid_right_retract_joint" type="revolute">
      <pose relative_to="mid_right_femur">-0.029923000000000002 0.039696000000000002 -0.018563 0 0 0</pose>
      <parent>mid_right_femur</parent>
      <child>mid_right_tibia</child>
      <axis>
        <xyz>1 0.00011 0</xyz>
        <limit>
          <lower>-1.5707960000000001</lower>
          <upper>1.5707960000000001</upper>
          <effort>100</effort>
          <velocity>100</velocity>
        </limit>
        <dynamics>
          <spring_reference>0</spring_reference>
          <spring_stiffness>0</spring_stiffness>
        </dynamics>
      </axis>
    </joint>
    <link name="mid_right_tibia">
      <pose relative_to="mid_right_retract_joint">0 0 0 0 0 0</pose>
      <inertial>
        <pose>0.015773574057860749 0.0058949324510389556 -0.043764578888882869 0 0 0</pose>
        <mass>0.02227943835487755</mass>
        <inertia>
          <ixx>1.939875416507577e-05</ixx>
          <ixy>2.4217580481392058e-08</ixy>
          <ixz>1.0778044150611289e-07</ixz>
          <iyy>1.9769186821995458e-05</iyy>
          <iyz>-3.8060319246942551e-06</iyz>
          <izz>3.9114277506498263e-06</izz>
        </inertia>
      </inertial>
      <collision name="mid_right_tibia_collision">
        <pose>0.0275 -0.125 0.01 0 0 3.1415926535897931</pose>
        <geometry>
          <mesh>
            <scale>0.001 0.001 0.001</scale>
            <uri>file:///home/thurdparty/Code/hexapod-ros/install/hexapod_description/share/hexapod_description/meshes/collision/tibia_right.stl</uri>
          </mesh>
        </geometry>
      </collision>
      <collision name="mid_right_tibia_fixed_joint_lump__foot_collision_collision_1">
        <pose>0.016 0 -0.070000000000000007 0 0 0</pose>
        <geometry>
          <sphere>
            <radius>0.0080000000000000002</radius>
          </sphere>
        </geometry>
      </collision>
      <visual name="mid_right_tibia_visual">
        <pose>0.0275 -0.125 0.01 0 0 3.1415926535897931</pose>
        <geometry>
          <mesh>
            <scale>0.001 0.001 0.001</scale>
            <uri>file:///home/thurdparty/Code/hexapod-ros/install/hexapod_description/share/hexapod_description/meshes/visual/tibia_right.stl</uri>
          </mesh>
        </geometry>
        <material>
          <diffuse>0.37500003 0.37500003 0.37500003 1</diffuse>
          <ambient>0.37500003 0.37500003 0.37500003 1</ambient>
        </material>
      </visual>
      <visual name="mid_right_tibia_fixed_joint_lump__mid_right_foot_visual_1">
        <pose>0.016 0 -0.070000000000000007 0 0 0</pose>
        <geometry>
          <sphere>
            <radius>0.0080000000000000002</radius>
          </sphere>
        </geometry>
        <material>
          <diffuse>0.37500003 0.37500003 0.37500003 1</diffuse>
          <ambient>0.37500003 0.37500003 0.37500003 1</ambient>
        </material>
      </visual>
    </link>
    <joint name="top_left_rotate_joint" type="revolute">
      <pose relative_to="base_footprint">0.074451000000000003 0.046823999999999998 0.1147 0 0 -0.78539816339744839</pose>
      <parent>base_footprint</parent>
      <child>top_left_cox</child>
      <axis>
        <xyz>0 0 -1</xyz>
        <limit>
          <lower>-1.5707960000000001</lower>
          <upper>1.5707960000000001</upper>
          <effort>100</effort>
          <velocity>100</velocity>
        </limit>
        <dynamics>
          <spring_reference>0</spring_reference>
          <spring_stiffness>0</spring_stiffness>
        </dynamics>
      </axis>
    </joint>
    <link name="top_left_cox">
      <pose relative_to="top_left_rotate_joint">0 0 0 0 0 0</pose>
      <inertial>
        <pose>0.0012733261090569091 0.014903434394979129 -0.020345821820411621 0 0 0</pose>
        <mass>0.01391683496290758</mass>
        <inertia>
          <ixx>3.0000000000000001e-06</ixx>
          <ixy>0</ixy>
          <ixz>0</ixz>
          <iyy>3.9999999999999998e-06</iyy>
          <iyz>0</iyz>
          <izz>3.0000000000000001e-06</izz>
        </inertia>
      </inertial>
      <collision name="top_left_cox_collision">
        <pose>-0.0036120000000000002 -0.056729000000000002 -0.030599999999999999 0 0 0</pose>
        <geometry>
          <mesh>
            <scale>0.001 0.001 0.001</scale>
            <uri>file:///home/thurdparty/Code/hexapod-ros/install/hexapod_description/share/hexapod_description/meshes/collision/cox_left.stl</uri>
          </mesh>
        </geometry>
      </collision>
      <visual name="top_left_cox_visual">
        <pose>-0.0036120000000000002 -0.056729000000000002 -0.030599999999999999 0 0 0</pose>
        <geometry>
          <mesh>
            <scale>0.001 0.001 0.001</scale>
            <uri>file:///home/thurdparty/Code/hexapod-ros/install/hexapod_description/share/hexapod_description/meshes/visual/cox_left.stl</uri>
          </mesh>
        </geometry>
        <material>
          <diffuse>0.37500003 0.37500003 0.37500003 1</diffuse>
          <ambient>0.37500003 0.37500003 0.37500003 1</ambient>
        </material>
      </visual>
    </link>
    <joint name="top_left_abduct_joint" type="revolute">
      <pose relative_to="top_left_cox">0.020937000000000001 0.029999999999999999 -0.021804 0 0 0</pose>
      <parent>top_left_cox</parent>
      <child>top_left_femur</child>
      <axis>
        <xyz>-1 0 0</xyz>
        <limit>
          <lower>-1.5707960000000001</lower>
          <upper>1.5707960000000001</upper>
          <effort>100</effort>
          <velocity>100</velocity>
        </limit>
        <dynamics>
          <spring_reference>0</spring_reference>
          <spring_stiffness>0</spring_stiffness>
        </dynamics>
      </axis>
    </joint>
    <link name="top_left_femur">
      <pose relative_to="top_left_abduct_joint">0 0 0 0 0 0</pose>
      <inertial>
        <pose>-0.01501165493471714 0.020989624323966821 -0.0057282527349048016 0 0 0</pose>
        <mass>0.01882378454979923</mass>
        <inertia>
          <ixx>5.0000000000000004e-06</ixx>
          <ixy>0</ixy>
          <ixz>0</ixz>
          <iyy>3.0000000000000001e-06</iyy>
          <iyz>1.9999999999999999e-06</iyz>
          <izz>5.0000000000000004e-06</izz>
        </inertia>
      </inertial>
      <collision name="top_left_femur_collision">
        <pose>-0.024549000000000001 -0.086729000000000001 -0.008796 0 0 0</pose>
        <geometry>
          <mesh>
            <scale>0.001 0.001 0.001</scale>
            <uri>file:///home/thurdparty/Code/hexapod-ros/install/hexapod_description/share/hexapod_description/meshes/collision/femur_left.stl</uri>
          </mesh>
        </geometry>
      </collision>
      <visual name="top_left_femur_visual">
        <pose>-0.024549000000000001 -0.086729000000000001 -0.008796 0 0 0</pose>
        <geometry>
          <mesh>
            <scale>0.001 0.001 0.001</scale>
            <uri>file:///home/thurdparty/Code/hexapod-ros/install/hexapod_description/share/hexapod_description/meshes/visual/femur_left.stl</uri>
          </mesh>
        </geometry>
        <material>
          <diffuse>0.37500003 0.37500003 0.37500003 1</diffuse>
          <ambient>0.37500003 0.37500003 0.37500003 1</ambient>
        </material>
      </visual>
    </link>
    <joint name="top_left_retract_joint" type="revolute">
      <pose relative_to="top_left_femur">-0.029923000000000002 0.039696000000000002 -0.018563 0 0 0</pose>
      <parent>top_left_femur</parent>
      <child>top_left_tibia</child>
      <axis>
        <xyz>1 0.00011 0</xyz>
        <limit>
          <lower>-1.5707960000000001</lower>
          <upper>1.5707960000000001</upper>
          <effort>100</effort>
          <velocity>100</velocity>
        </limit>
        <dynamics>
          <spring_reference>0</spring_reference>
          <spring_stiffness>0</spring_stiffness>
        </dynamics>
      </axis>
    </joint>
    <link name="top_left_tibia">
      <pose relative_to="top_left_retract_joint">0 0 0 0 0 0</pose>
      <inertial>
        <pose>0.015773574057860749 0.0058949324510389556 -0.043764578888882869 0 0 0</pose>
        <mass>0.02227943835487755</mass>
        <inertia>
          <ixx>1.939875416507577e-05</ixx>
          <ixy>2.4217580481392058e-08</ixy>
          <ixz>1.0778044150611289e-07</ixz>
          <iyy>1.9769186821995458e-05</iyy>
          <iyz>-3.8060319246942551e-06</iyz>
          <izz>3.9114277506498263e-06</izz>
        </inertia>
      </inertial>
      <collision name="top_left_tibia_collision">
        <pose>0.0053740000000000003 -0.12642500000000001 0.0097669999999999996 0 0 0</pose>
        <geometry>
          <mesh>
            <scale>0.001 0.001 0.001</scale>
            <uri>file:///home/thurdparty/Code/hexapod-ros/install/hexapod_description/share/hexapod_description/meshes/collision/tibia_left.stl</uri>
          </mesh>
        </geometry>
      </collision>
      <collision name="top_left_tibia_fixed_joint_lump__foot_collision_collision_1">
        <pose>0.016 0 -0.070000000000000007 0 0 0</pose>
        <geometry>
          <sphere>
            <radius>0.0080000000000000002</radius>
          </sphere>
        </geometry>
      </collision>
      <visual name="top_left_tibia_visual">
        <pose>0.0053740000000000003 -0.12642500000000001 0.0097669999999999996 0 0 0</pose>
        <geometry>
          <mesh>
            <scale>0.001 0.001 0.001</scale>
            <uri>file:///home/thurdparty/Code/hexapod-ros/install/hexapod_description/share/hexapod_description/meshes/visual/tibia_left.stl</uri>
          </mesh>
        </geometry>
        <material>
          <diffuse>0.37500003 0.37500003 0.37500003 1</diffuse>
          <ambient>0.37500003 0.37500003 0.37500003 1</ambient>
        </material>
      </visual>
      <visual name="top_left_tibia_fixed_joint_lump__top_left_foot_visual_1">
        <pose>0.016 0 -0.070000000000000007 0 0 0</pose>
        <geometry>
          <sphere>
            <radius>0.0080000000000000002</radius>
          </sphere>
        </geometry>
        <material>
          <diffuse>0.37500003 0.37500003 0.37500003 1</diffuse>
          <ambient>0.37500003 0.37500003 0.37500003 1</ambient>
        </material>
      </visual>
    </link>
    <joint name="top_right_rotate_joint" type="revolute">
      <pose relative_to="base_footprint">0.075633000000000006 -0.046740999999999998 0.1147 0 0 -2.3561944901923448</pose>
      <parent>base_footprint</parent>
      <child>top_right_cox</child>
      <axis>
        <xyz>0 0 -1</xyz>
        <limit>
          <lower>-1.5707960000000001</lower>
          <upper>1.5707960000000001</upper>
          <effort>100</effort>
          <velocity>100</velocity>
        </limit>
        <dynamics>
          <spring_reference>0</spring_reference>
          <spring_stiffness>0</spring_stiffness>
        </dynamics>
      </axis>
    </joint>
    <link name="top_right_cox">
      <pose relative_to="top_right_rotate_joint">0 0 0 0 0 0</pose>
      <inertial>
        <pose>0.0012733261090569091 0.014903434394979129 -0.020345821820411621 0 0 0</pose>
        <mass>0.01391683496290758</mass>
        <inertia>
          <ixx>3.0000000000000001e-06</ixx>
          <ixy>0</ixy>
          <ixz>0</ixz>
          <iyy>3.9999999999999998e-06</iyy>
          <iyz>0</iyz>
          <izz>3.0000000000000001e-06</izz>
        </inertia>
      </inertial>
      <collision name="top_right_cox_collision">
        <pose>0.0035000000000000001 -0.055 -0.030599999999999999 0 0 3.1415926535897931</pose>
        <geometry>
          <mesh>
            <scale>0.001 0.001 0.001</scale>
            <uri>file:///home/thurdparty/Code/hexapod-ros/install/hexapod_description/share/hexapod_description/meshes/collision/cox_right.stl</uri>
          </mesh>
        </geometry>
      </collision>
      <visual name="top_right_cox_visual">
        <pose>0.0035000000000000001 -0.055 -0.030599999999999999 0 0 3.1415926535897931</pose>
        <geometry>
          <mesh>
            <scale>0.001 0.001 0.001</scale>
            <uri>file:///home/thurdparty/Code/hexapod-ros/install/hexapod_description/share/hexapod_description/meshes/visual/cox_right.stl</uri>
          </mesh>
        </geometry>
        <material>
          <diffuse>0.37500003 0.37500003 0.37500003 1</diffuse>
          <ambient>0.37500003 0.37500003 0.37500003 1</ambient>
        </material>
      </visual>
    </link>
    <joint name="top_right_abduct_joint" type="revolute">
      <pose relative_to="top_right_cox">0.0077499999999999999 0.029999999999999999 -0.021804 0 0 0</pose>
      <parent>top_right_cox</parent>
      <child>top_right_femur</child>
      <axis>
        <xyz>-1 0 0</xyz>
        <limit>
          <lower>-1.5707960000000001</lower>
          <upper>1.5707960000000001</upper>
          <effort>100</effort>
          <velocity>100</velocity>
        </limit>
        <dynamics>
          <spring_reference>0</spring_reference>
          <spring_stiffness>0</spring_stiffness>
        </dynamics>
      </axis>
    </joint>
    <link name="top_right_femur">
      <pose relative_to="top_right_abduct_joint">0 0 0 0 0 0</pose>
      <inertial>
        <pose>-0.01501165493471714 0.020989624323966821 -0.0057282527349048016 0 0 0</pose>
        <mass>0.01882378454979923</mass>
        <inertia>
          <ixx>5.0000000000000004e-06</ixx>
          <ixy>0</ixy>
          <ixz>0</ixz>
          <iyy>3.0000000000000001e-06</iyy>
          <iyz>1.9999999999999999e-06</iyz>
          <izz>5.0000000000000004e-06</izz>
        </inertia>
      </inertial>
      <collision name="top_right_femur_collision">
        <pose>-0.0035000000000000001 -0.085000000000000006 -0.0085000000000000006 0 0 3.1415926535897931</pose>
        <geometry>
          <mesh>
            <scale>0.001 0.001 0.001</scale>
            <uri>file:///home/thurdparty/Code/hexapod-ros/install/hexapod_description/share/hexapod_description/meshes/collision/femur_right.stl</uri>
          </mesh>
        </geometry>
      </collision>
      <visual name="top_right_femur_visual">
        <pose>-0.0035000000000000001 -0.085000000000000006 -0.0085000000000000006 0 0 3.1415926535897931</pose>
        <geometry>
          <mesh>
            <scale>0.001 0.001 0.001</scale>
            <uri>file:///home/thurdparty/Code/hexapod-ros/install/hexapod_description/share/hexapod_description/meshes/visual/femur_right.stl</uri>
          </mesh>
        </geometry>
        <material>
          <diffuse>0.37500003 0.37500003 0.37500003 1</diffuse>
          <ambient>0.37500003 0.37500003 0.37500003 1</ambient>
        </material>
      </visual>
    </link>
    <joint name="top_right_retract_joint" type="revolute">
      <pose relative_to="top_right_femur">-0.029923000000000002 0.039696000000000002 -0.018563 0 0 0</pose>
      <parent>top_right_femur</parent>
      <child>top_right_tibia</child>
      <axis>
        <xyz>1 0.00011 0</xyz>
        <limit>
          <lower>-1.5707960000000001</lower>
          <upper>1.5707960000000001</upper>
          <effort>100</effort>
          <velocity>100</velocity>
        </limit>
        <dynamics>
          <spring_reference>0</spring_reference>
          <spring_stiffness>0</spring_stiffness>
        </dynamics>
      </axis>
    </joint>
    <link name="top_right_tibia">
      <pose relative_to="top_right_retract_joint">0 0 0 0 0 0</pose>
      <inertial>
        <pose>0.015773574057860749 0.0058949324510389556 -0.043764578888882869 0 0 0</pose>
        <mass>0.02227943835487755</mass>
        <inertia>
          <ixx>1.939875416507577e-05</ixx>
          <ixy>2.4217580481392058e-08</ixy>
          <ixz>1.0778044150611289e-07</ixz>
          <iyy>1.9769186821995458e-05</iyy>
          <iyz>-3.8060319246942551e-06</iyz>
          <izz>3.9114277506498263e-06</izz>
        </inertia>
      </inertial>
      <collision name="top_right_tibia_collision">
        <pose>0.0275 -0.125 0.01 0 0 3.1415926535897931</pose>
        <geometry>
          <mesh>
            <scale>0.001 0.001 0.001</scale>
            <uri>file:///home/thurdparty/Code/hexapod-ros/install/hexapod_description/share/hexapod_description/meshes/collision/tibia_right.stl</uri>
          </mesh>
        </geometry>
      </collision>
      <collision name="top_right_tibia_fixed_joint_lump__foot_collision_collision_1">
        <pose>0.016 0 -0.070000000000000007 0 0 0</pose>
        <geometry>
          <sphere>
            <radius>0.0080000000000000002</radius>
          </sphere>
        </geometry>
      </collision>
      <visual name="top_right_tibia_visual">
        <pose>0.0275 -0.125 0.01 0 0 3.1415926535897931</pose>
        <geometry>
          <mesh>
            <scale>0.001 0.001 0.001</scale>
            <uri>file:///home/thurdparty/Code/hexapod-ros/install/hexapod_description/share/hexapod_description/meshes/visual/tibia_right.stl</uri>
          </mesh>
        </geometry>
        <material>
          <diffuse>0.37500003 0.37500003 0.37500003 1</diffuse>
          <ambient>0.37500003 0.37500003 0.37500003 1</ambient>
        </material>
      </visual>
      <visual name="top_right_tibia_fixed_joint_lump__top_right_foot_visual_1">
        <pose>0.016 0 -0.070000000000000007 0 0 0</pose>
        <geometry>
          <sphere>
            <radius>0.0080000000000000002</radius>
          </sphere>
        </geometry>
        <material>
          <diffuse>0.37500003 0.37500003 0.37500003 1</diffuse>
          <ambient>0.37500003 0.37500003 0.37500003 1</ambient>
        </material>
      </visual>
    </link>
    <plugin filename="libgz_ros2_control-system.so" name="gz_ros2_control::GazeboSimROS2ControlPlugin">
      <parameters>/home/thurdparty/Code/hexapod-ros/install/hexapod_sim/share/hexapod_sim/config/hexapod_controllers.yaml</parameters>
      <ros2_control name="FakeSystem" type="system">
        <hardware>
          <plugin>gz_ros2_control/GazeboSimSystem</plugin>
        </hardware>
        <joint name="arm_rotator_joint">
          <command_interface name="position">
            <param name="min">-1.5</param>
            <param name="max">1.5</param>
          </command_interface>
          <state_interface name="position"></state_interface>
        </joint>
        <joint name="arm_abductor_joint">
          <command_interface name="position">
            <param name="min">-1.5</param>
            <param name="max">1.5</param>
          </command_interface>
          <state_interface name="position"></state_interface>
        </joint>
        <joint name="arm_retractor_joint">
          <command_interface name="position">
            <param name="min">-1.5</param>
            <param name="max">1.5</param>
          </command_interface>
          <state_interface name="position"></state_interface>
        </joint>
        <joint name="top_left_rotate_joint">
          <command_interface name="position">
            <param name="min">-1.5</param>
            <param name="max">1.5</param>
          </command_interface>
          <state_interface name="position"></state_interface>
        </joint>
        <joint name="top_left_abduct_joint">
          <command_interface name="position">
            <param name="min">-1.5</param>
            <param name="max">1.5</param>
          </command_interface>
          <state_interface name="position"></state_interface>
        </joint>
        <joint name="top_left_retract_joint">
          <command_interface name="position">
            <param name="min">-1.5</param>
            <param name="max">1.5</param>
          </command_interface>
          <state_interface name="position"></state_interface>
        </joint>
        <joint name="mid_left_rotate_joint">
          <command_interface name="position">
            <param name="min">-1.5</param>
            <param name="max">1.5</param>
          </command_interface>
          <state_interface name="position"></state_interface>
        </joint>
        <joint name="mid_left_abduct_joint">
          <command_interface name="position">
            <param name="min">-1.5</param>
            <param name="max">1.5</param>
          </command_interface>
          <state_interface name="position"></state_interface>
        </joint>
        <joint name="mid_left_retract_joint">
          <command_interface name="position">
            <param name="min">-1.5</param>
            <param name="max">1.5</param>
          </command_interface>
          <state_interface name="position"></state_interface>
        </joint>
        <joint name="bottom_left_rotate_joint">
          <command_interface name="position">
            <param name="min">-1.5</param>
            <param name="max">1.5</param>
          </command_interface>
          <state_interface name="position"></state_interface>
        </joint>
        <joint name="bottom_left_abduct_joint">
          <command_interface name="position">
            <param name="min">-1.5</param>
            <param name="max">1.5</param>
          </command_interface>
          <state_interface name="position"></state_interface>
        </joint>
        <joint name="bottom_left_retract_joint">
          <command_interface name="position">
            <param name="min">-1.5</param>
            <param name="max">1.5</param>
          </command_interface>
          <state_interface name="position"></state_interface>
        </joint>
        <joint name="top_right_rotate_joint">
          <command_interface name="position">
            <param name="min">-1.5</param>
            <param name="max">1.5</param>
          </command_interface>
          <state_interface name="position"></state_interface>
        </joint>
        <joint name="top_right_abduct_joint">
          <command_interface name="position">
            <param name="min">-1.5</param>
            <param name="max">1.5</param>
          </command_interface>
          <state_interface name="position"></state_interface>
        </joint>
        <joint name="top_right_retract_joint">
          <command_interface name="position">
            <param name="min">-1.5</param>
            <param name="max">1.5</param>
          </command_interface>
          <state_interface name="position"></state_interface>
        </joint>
        <joint name="mid_right_rotate_joint">
          <command_interface name="position">
            <param name="min">-1.5</param>
            <param name="max">1.5</param>
          </command_interface>
          <state_interface name="position"></state_interface>
        </joint>
        <joint name="mid_right_abduct_joint">
          <command_interface name="position">
            <param name="min">-1.5</param>
            <param name="max">1.5</param>
          </command_interface>
          <state_interface name="position"></state_interface>
        </joint>
        <joint name="mid_right_retract_joint">
          <command_interface name="position">
            <param name="min">-1.5</param>
            <param name="max">1.5</param>
          </command_interface>
          <state_interface name="position"></state_interface>
        </joint>
        <joint name="bottom_right_rotate_joint">
          <command_interface name="position">
            <param name="min">-1.5</param>
            <param name="max">1.5</param>
          </command_interface>
          <state_interface name="position"></state_interface>
        </joint>
        <joint name="bottom_right_abduct_joint">
          <command_interface name="position">
            <param name="min">-1.5</param>
            <param name="max">1.5</param>
          </command_interface>
          <state_interface name="position"></state_interface>
        </joint>
        <joint name="bottom_right_retract_joint">
          <command_interface name="position">
            <param name="min">-1.5</param>
            <param name="max">1.5</param>
          </command_interface>
          <state_interface name="position"></state_interface>
        </joint>
      </ros2_control>
    </plugin>
    <!-- <plugin filename="gz-sim-sensors-system" name="gz::sim::systems::Sensors"> -->
    <!--   <render_engine>ogre2</render_engine> -->
    <!-- </plugin> -->
    <frame attached_to="base_link" name="arm_base_mount_joint">
      <pose>0.025588 -0.019422999999999999 0.044900000000000002 0 0 0</pose>
    </frame>
    <frame attached_to="arm_base_mount_joint" name="arm_base">
      <pose>0 0 0 0 0 0</pose>
    </frame>
    <frame attached_to="arm_retractor" name="camera_case_cover_joint">
      <pose>-0.012500000000000001 0 0.055 -1.5707963267948957 -1.5707963267948966 0</pose>
    </frame>
    <frame attached_to="camera_case_cover_joint" name="camera_case_cover">
      <pose>0 0 0 0 0 0</pose>
    </frame>
    <frame attached_to="depth_camera_link" name="depth_camera_optical_joint">
      <pose>0 0 0 -1.5707963267948959 -5.5511151231257827e-17 -1.5707963267948959</pose>
    </frame>
    <frame attached_to="depth_camera_optical_joint" name="depth_camera_optical_frame">
      <pose>0 0 0 0 0 0</pose>
    </frame>
    <frame attached_to="arm_retractor" name="depth_camera_link_joint">
      <pose>-0.012500000000000001 0 0.055 -1.5707963267948957 -1.5707963267948966 0</pose>
    </frame>
    <frame attached_to="depth_camera_link_joint" name="depth_camera_link">
      <pose>0 0 0 0 0 0</pose>
    </frame>
    <frame attached_to="base_footprint" name="base_link_joint">
      <pose>0 0 0.085000000000000006 0 0 0</pose>
    </frame>
    <frame attached_to="base_link_joint" name="base_link">
      <pose>0 0 0 0 0 0</pose>
    </frame>
    <frame attached_to="bottom_left_tibia" name="bottom_left_foot_joint">
      <pose>0.016 0 -0.070000000000000007 0 0 0</pose>
    </frame>
    <frame attached_to="bottom_left_foot_joint" name="bottom_left_foot">
      <pose>0 0 0 0 0 0</pose>
    </frame>
    <frame attached_to="bottom_right_tibia" name="bottom_right_foot_joint">
      <pose>0.016 0 -0.070000000000000007 0 0 0</pose>
    </frame>
    <frame attached_to="bottom_right_foot_joint" name="bottom_right_foot">
      <pose>0 0 0 0 0 0</pose>
    </frame>
    <frame attached_to="mid_left_tibia" name="mid_left_foot_joint">
      <pose>0.016 0 -0.070000000000000007 0 0 0</pose>
    </frame>
    <frame attached_to="mid_left_foot_joint" name="mid_left_foot">
      <pose>0 0 0 0 0 0</pose>
    </frame>
    <frame attached_to="mid_right_tibia" name="mid_right_foot_joint">
      <pose>0.016 0 -0.070000000000000007 0 0 0</pose>
    </frame>
    <frame attached_to="mid_right_foot_joint" name="mid_right_foot">
      <pose>0 0 0 0 0 0</pose>
    </frame>
    <frame attached_to="top_left_tibia" name="top_left_foot_joint">
      <pose>0.016 0 -0.070000000000000007 0 0 0</pose>
    </frame>
    <frame attached_to="top_left_foot_joint" name="top_left_foot">
      <pose>0 0 0 0 0 0</pose>
    </frame>
    <frame attached_to="top_right_tibia" name="top_right_foot_joint">
      <pose>0.016 0 -0.070000000000000007 0 0 0</pose>
    </frame>
    <frame attached_to="top_right_foot_joint" name="top_right_foot">
      <pose>0 0 0 0 0 0</pose>
    </frame>
  </model>
</sdf>
