<?xml version="1.0" ?>
<!-- =================================================================================== -->
<!-- |    This document was autogenerated by xacro from hexapod_description/robots/hexapod.urdf.xacro | -->
<!-- |    EDITING THIS FILE BY HAND IS NOT RECOMMENDED                                 | -->
<!-- =================================================================================== -->
<!-- Basic differential drive mobile base -->
<robot name="hexapod">
  <gazebo>
    <plugin filename="libgz_ros2_control-system" name="gz_ros2_control::GazeboSimROS2ControlPlugin">
      <parameters>/home/mustafayousif/Code/hexapod_robot_harmonic/install/hexapod_description/share/hexapod_description/config/hexapod_controllers.yaml</parameters>
    </plugin>
  </gazebo>
  <!-- Init colour -->
  <material name="black">
    <color rgba="0.0 0.0 0.0 1.0"/>
  </material>
  <material name="dark">
    <color rgba="0.3 0.3 0.3 1.0"/>
  </material>
  <material name="light_black">
    <color rgba="0.4 0.4 0.4 1.0"/>
  </material>
  <material name="blue">
    <color rgba="0.0 0.0 0.8 1.0"/>
  </material>
  <material name="green">
    <color rgba="0.0 0.8 0.0 1.0"/>
  </material>
  <material name="grey">
    <color rgba="0.5 0.5 0.5 1.0"/>
  </material>
  <material name="orange">
    <color rgba="1.0 0.4235294117647059 0.0392156862745098 1.0"/>
  </material>
  <material name="brown">
    <color rgba="0.8705882352941177 0.8117647058823529 0.7647058823529411 1.0"/>
  </material>
  <material name="red">
    <color rgba="0.8 0.0 0.0 1.0"/>
  </material>
  <material name="white">
    <color rgba="1.0 1.0 1.0 1.0"/>
  </material>
  <!-- =============== Link & Joint =============== -->
  <!-- Base -->
  <link name="base_footprint"/>
  <!-- Joints -->
  <joint name="base_link_joint" type="fixed">
    <origin rpy="0 0 0" xyz="0 0 0.8"/>
    <parent link="base_footprint"/>
    <child link="base_link"/>
  </joint>
  <!-- Links -->
  <link name="base_link">
    <inertial>
      <origin rpy="0 0 0" xyz="0.005334608688478278 0.0002689766590861973 0.0184918721125776"/>
      <mass value="0.1730647056842735"/>
      <inertia ixx="0.000266" ixy="4e-06" ixz="-1e-06" iyy="0.000406" iyz="-0.0" izz="0.0006"/>
    </inertial>
    <visual>
      <origin rpy="0 0 0" xyz="0 0 0"/>
      <geometry>
        <mesh filename="file:///home/mustafayousif/Code/hexapod_robot_harmonic/install/hexapod_description/share/hexapod_description/meshes/base/base_link.stl" scale="0.001 0.001 0.001"/>
      </geometry>
      <material name="dark"/>
    </visual>
    <collision>
      <origin rpy="0 0 0" xyz="0 0 0"/>
      <geometry>
        <mesh filename="file:///home/mustafayousif/Code/hexapod_robot_harmonic/install/hexapod_description/share/hexapod_description/meshes/base/base_link.stl" scale="0.001 0.001 0.001"/>
      </geometry>
    </collision>
  </link>
  <!-- Gazebo Properties -->
  <gazebo reference="base_link">
    <selfCollide>false</selfCollide>
    <mu1 value="0.05"/>
    <mu2 value="0.05"/>
  </gazebo>
  <!-- Joints -->
  <joint name="arm_base_mount_joint" type="fixed">
    <origin rpy="0 0 0" xyz="0.025588 -0.019423 0.0449"/>
    <parent link="base_link"/>
    <child link="arm_base"/>
  </joint>
  <joint name="arm_rotator_joint" type="continuous">
    <origin rpy="0 0 0" xyz="8.8e-05 0.019999 0.02995"/>
    <parent link="arm_base"/>
    <child link="arm_rotator"/>
    <axis xyz="0.0 -0.0 -1.0"/>
    <limit effort="100" lower="-1.570796" upper="1.570796" velocity="100"/>
  </joint>
  <joint name="arm_abductor_joint" type="revolute">
    <origin rpy="0 0 0" xyz="0.014582 0.00069 0.013923"/>
    <parent link="arm_rotator"/>
    <child link="arm_abductor"/>
    <axis xyz="-1.0 0.0 -0.0"/>
    <limit effort="100" lower="-1.570796" upper="1.570796" velocity="100"/>
  </joint>
  <joint name="arm_retractor_joint" type="revolute">
    <origin rpy="0 0 0" xyz="-0.000401 0.0 0.046709"/>
    <parent link="arm_abductor"/>
    <child link="arm_retractor"/>
    <axis xyz="-0.999993 0.0 -0.003676"/>
    <limit effort="100" lower="-1.570796" upper="1.570796" velocity="100"/>
  </joint>
  <!-- Links -->
  <link name="arm_rotator">
    <inertial>
      <origin rpy="0 0 0" xyz="-0.00046642883527773724 0.0027188082250819237 0.00576546998065737"/>
      <mass value="0.02623546025799875"/>
      <inertia ixx="4e-06" ixy="0.0" ixz="0.0" iyy="4e-06" iyz="-0.0" izz="5e-06"/>
    </inertial>
    <visual>
      <origin rpy="0 0 0" xyz="-0.025676 -0.000576 -0.07485"/>
      <geometry>
        <mesh filename="file:///home/mustafayousif/Code/hexapod_robot_harmonic/install/hexapod_description/share/hexapod_description/meshes/arm/rotator.stl" scale="0.001 0.001 0.001"/>
      </geometry>
      <material name="dark"/>
    </visual>
    <collision>
      <origin rpy="0 0 0" xyz="-0.025676 -0.000576 -0.07485"/>
      <geometry>
        <mesh filename="file:///home/mustafayousif/Code/hexapod_robot_harmonic/install/hexapod_description/share/hexapod_description/meshes/arm/rotator.stl" scale="0.001 0.001 0.001"/>
      </geometry>
    </collision>
  </link>
  <link name="arm_abductor">
    <inertial>
      <origin rpy="0 0 0" xyz="-0.014167725035919117 3.5639852713031765e-07 0.031090662760010462"/>
      <mass value="0.016534189067873267"/>
      <inertia ixx="5e-06" ixy="-0.0" ixz="1e-06" iyy="7e-06" iyz="-0.0" izz="2e-06"/>
    </inertial>
    <visual>
      <origin rpy="0 0 0" xyz="-0.040258 -0.001266 -0.088773"/>
      <geometry>
        <mesh filename="file:///home/mustafayousif/Code/hexapod_robot_harmonic/install/hexapod_description/share/hexapod_description/meshes/arm/abductor.stl" scale="0.001 0.001 0.001"/>
      </geometry>
      <material name="dark"/>
    </visual>
    <collision>
      <origin rpy="0 0 0" xyz="-0.040258 -0.001266 -0.088773"/>
      <geometry>
        <mesh filename="file:///home/mustafayousif/Code/hexapod_robot_harmonic/install/hexapod_description/share/hexapod_description/meshes/arm/abductor.stl" scale="0.001 0.001 0.001"/>
      </geometry>
    </collision>
  </link>
  <link name="arm_retractor">
    <inertial>
      <origin rpy="0 0 0" xyz="-0.011027322351092845 -5.220911472792085e-05 0.023364114206742087"/>
      <mass value="0.015328010788351278"/>
      <inertia ixx="3e-06" ixy="0.0" ixz="-0.0" iyy="5e-06" iyz="0.0" izz="4e-06"/>
    </inertial>
    <visual>
      <origin rpy="0 0 0" xyz="-0.039857 -0.001266 -0.135482"/>
      <geometry>
        <mesh filename="file:///home/mustafayousif/Code/hexapod_robot_harmonic/install/hexapod_description/share/hexapod_description/meshes/arm/retractor.stl" scale="0.001 0.001 0.001"/>
      </geometry>
      <material name="dark"/>
    </visual>
    <collision>
      <origin rpy="0 0 0" xyz="-0.039857 -0.001266 -0.135482"/>
      <geometry>
        <mesh filename="file:///home/mustafayousif/Code/hexapod_robot_harmonic/install/hexapod_description/share/hexapod_description/meshes/arm/retractor.stl" scale="0.001 0.001 0.001"/>
      </geometry>
    </collision>
  </link>
  <link name="arm_base">
    <inertial>
      <origin rpy="0 0 0" xyz="0.004115093716825637 0.020000308654227843 0.01035421864114821"/>
      <mass value="0.014628769254330782"/>
      <inertia ixx="2e-06" ixy="0.0" ixz="-0.0" iyy="3e-06" iyz="0.0" izz="2e-06"/>
    </inertial>
    <visual>
      <origin rpy="0 0 0" xyz="-0.025588 0.019423 -0.0449"/>
      <geometry>
        <mesh filename="file:///home/mustafayousif/Code/hexapod_robot_harmonic/install/hexapod_description/share/hexapod_description/meshes/arm/base.stl" scale="0.001 0.001 0.001"/>
      </geometry>
      <material name="dark"/>
    </visual>
    <collision>
      <origin rpy="0 0 0" xyz="-0.025588 0.019423 -0.0449"/>
      <geometry>
        <mesh filename="file:///home/mustafayousif/Code/hexapod_robot_harmonic/install/hexapod_description/share/hexapod_description/meshes/arm/base.stl" scale="0.001 0.001 0.001"/>
      </geometry>
    </collision>
  </link>
  <!-- Joints -->
  <joint name="camera_case_mount" type="fixed">
    <origin rpy="0 0 0" xyz="-0.081856 -0.02175 -0.054547"/>
    <parent link="arm_retractor"/>
    <child link="camera_link"/>
  </joint>
  <!-- Links -->
  <link name="camera_link">
    <inertial>
      <origin rpy="0 0 0" xyz="0.07257325961305607 0.023187735063927437 0.09454807900867684"/>
      <mass value="0.00672643608404174"/>
      <inertia ixx="1e-06" ixy="0.0" ixz="0.0" iyy="2e-06" iyz="0.0" izz="3e-06"/>
    </inertial>
    <visual>
      <origin rpy="0 0 0" xyz="0.041999 0.020484 -0.080935"/>
      <geometry>
        <mesh filename="file:///home/mustafayousif/Code/hexapod_robot_harmonic/install/hexapod_description/share/hexapod_description/meshes/sensors/camera/camera.stl" scale="0.001 0.001 0.001"/>
      </geometry>
      <material name="red"/>
    </visual>
    <collision>
      <origin rpy="0 0 0" xyz="0.041999 0.020484 -0.080935"/>
      <geometry>
        <mesh filename="file:///home/mustafayousif/Code/hexapod_robot_harmonic/install/hexapod_description/share/hexapod_description/meshes/sensors/camera/camera.stl" scale="0.001 0.001 0.001"/>
      </geometry>
    </collision>
  </link>
  <!-- Gazebo -->
  <gazebo reference="camera_link">
    <sensor name="depth_camera" type="depth_camera">
      <always_on>true</always_on>
      <visualize>true</visualize>
      <update_rate>60</update_rate>
      <topic>depth_camera/depth/image_raw</topic>
      <frame_id>camera_depth_frame</frame_id>
      <camera name="sipeed Max A10">
        <camera_info_topic>depth_camera/depth/camera_info</camera_info_topic>
        <horizontal_fov>1.02974</horizontal_fov>
        <image>
          <width>1920</width>
          <height>1080</height>
          <format>R_FLOAT32</format>
        </image>
        <clip>
          <near>0.02</near>
          <far>300</far>
        </clip>
        <noise>
          <type>gaussian</type>
          <mean>0.0</mean>
          <stddev>0.007</stddev>
        </noise>
      </camera>
    </sensor>
  </gazebo>
  <!-- Joints -->
  <joint name="top_left_rotate_joint" type="revolute">
    <origin rpy="0 0 -0.785398185" xyz="0.074451 0.046824 0.0297"/>
    <parent link="base_link"/>
    <child link="top_left_cox"/>
    <axis xyz="-0.0 0.0 -1.0"/>
    <limit effort="100" lower="-1.570796" upper="1.570796" velocity="100"/>
  </joint>
  <joint name="top_left_abduct_joint" type="revolute">
    <origin rpy="0 0 0" xyz="0.020937 0.03 -0.021804"/>
    <axis xyz="-1.0 -0.0 -0.0"/>
    <limit effort="100" lower="-1.570796" upper="1.570796" velocity="100"/>
    <parent link="top_left_cox"/>
    <child link="top_left_femur"/>
  </joint>
  <joint name="top_left_retract_joint" type="revolute">
    <origin rpy="0 0 0" xyz="-0.029923 0.039696 -0.018563"/>
    <parent link="top_left_femur"/>
    <child link="top_left_tibia"/>
    <axis xyz="0.707029 0.707185 0.0"/>
    <limit effort="100" lower="-1.570796" upper="1.570796" velocity="100"/>
  </joint>
  <link name="top_left_cox">
    <inertial>
      <origin rpy="0 0 0" xyz="0.0012733261090569089 0.014903434394979126 -0.02034582182041162"/>
      <mass value="0.01391683496290758"/>
      <inertia ixx="3e-06" ixy="-0.0" ixz="0.0" iyy="4e-06" iyz="0.0" izz="3e-06"/>
    </inertial>
    <visual>
      <origin rpy="0 0 0" xyz="-0.003612 -0.056729 -0.0306"/>
      <geometry>
        <mesh filename="file:///home/mustafayousif/Code/hexapod_robot_harmonic/install/hexapod_description/share/hexapod_description/meshes/leg/cox_left_mid.stl" scale="0.001 0.001 0.001"/>
      </geometry>
      <material name="dark"/>
    </visual>
    <collision>
      <origin rpy="0 0 0" xyz="-0.003612 -0.056729 -0.0306"/>
      <geometry>
        <mesh filename="file:///home/mustafayousif/Code/hexapod_robot_harmonic/install/hexapod_description/share/hexapod_description/meshes/leg/cox_left_mid.stl" scale="0.001 0.001 0.001"/>
      </geometry>
    </collision>
  </link>
  <link name="top_left_tibia">
    <inertial>
      <origin rpy="0 0 0" xyz="0.015589179677926173 0.010695585608516162 -0.0223992522730315"/>
      <mass value="0.012279438354877548"/>
      <inertia ixx="5e-06" ixy="0.0" ixz="0.0" iyy="6e-06" iyz="-1e-06" izz="2e-06"/>
    </inertial>
    <visual>
      <origin rpy="0 0 0" xyz="0.005374 -0.126425 0.009767"/>
      <geometry>
        <mesh filename="file:///home/mustafayousif/Code/hexapod_robot_harmonic/install/hexapod_description/share/hexapod_description/meshes/leg/tibia_left_mid.stl" scale="0.001 0.001 0.001"/>
      </geometry>
      <material name="dark"/>
    </visual>
    <collision>
      <origin rpy="0 0 0" xyz="0.005374 -0.126425 0.009767"/>
      <geometry>
        <mesh filename="file:///home/mustafayousif/Code/hexapod_robot_harmonic/install/hexapod_description/share/hexapod_description/meshes/leg/tibia_left_mid.stl" scale="0.001 0.001 0.001"/>
      </geometry>
    </collision>
  </link>
  <link name="top_left_femur">
    <inertial>
      <origin rpy="0 0 0" xyz="-0.015011654934717145 0.020989624323966824 -0.005728252734904802"/>
      <mass value="0.018823784549799234"/>
      <inertia ixx="5e-06" ixy="0.0" ixz="-0.0" iyy="3e-06" iyz="2e-06" izz="5e-06"/>
    </inertial>
    <visual>
      <origin rpy="0 0 0" xyz="-0.024549 -0.086729 -0.008796"/>
      <geometry>
        <mesh filename="file:///home/mustafayousif/Code/hexapod_robot_harmonic/install/hexapod_description/share/hexapod_description/meshes/leg/femur_left_mid.stl" scale="0.001 0.001 0.001"/>
      </geometry>
      <material name="dark"/>
    </visual>
    <collision>
      <origin rpy="0 0 0" xyz="-0.024549 -0.086729 -0.008796"/>
      <geometry>
        <mesh filename="file:///home/mustafayousif/Code/hexapod_robot_harmonic/install/hexapod_description/share/hexapod_description/meshes/leg/femur_left_mid.stl" scale="0.001 0.001 0.001"/>
      </geometry>
    </collision>
  </link>
  <transmission name="top_left_rotate_joint_tran">
    <type>transmission_interface/SimpleTransmission</type>
    <joint name="top_left_rotate_joint">
      <hardwareInterface>hardware_interface/EffortJointInterface</hardwareInterface>
    </joint>
    <actuator name="top_left_rotate_joint_actr">
      <hardwareInterface>hardware_interface/EffortJointInterface</hardwareInterface>
      <mechanicalReduction>1</mechanicalReduction>
    </actuator>
  </transmission>
  <transmission name="top_left_abduct_joint_tran">
    <type>transmission_interface/SimpleTransmission</type>
    <joint name="top_left_abduct_joint">
      <hardwareInterface>hardware_interface/EffortJointInterface</hardwareInterface>
    </joint>
    <actuator name="top_left_abduct_joint_actr">
      <hardwareInterface>hardware_interface/EffortJointInterface</hardwareInterface>
      <mechanicalReduction>1</mechanicalReduction>
    </actuator>
  </transmission>
  <transmission name="top_left_retract_joint_tran">
    <type>transmission_interface/SimpleTransmission</type>
    <joint name="top_left_retract_joint">
      <hardwareInterface>hardware_interface/EffortJointInterface</hardwareInterface>
    </joint>
    <actuator name="top_left_retract_joint_actr">
      <hardwareInterface>hardware_interface/EffortJointInterface</hardwareInterface>
      <mechanicalReduction>1</mechanicalReduction>
    </actuator>
  </transmission>
  <!-- Joints -->
  <joint name="mid_left_rotate_joint" type="revolute">
    <origin rpy="0 0 0" xyz="0.003612 0.056729 0.0306"/>
    <parent link="base_link"/>
    <child link="mid_left_cox"/>
    <axis xyz="-0.0 0.0 -1.0"/>
    <limit effort="100" lower="-1.570796" upper="1.570796" velocity="100"/>
  </joint>
  <joint name="mid_left_abduct_joint" type="revolute">
    <origin rpy="0 0 0" xyz="0.020937 0.03 -0.021804"/>
    <axis xyz="-1.0 -0.0 -0.0"/>
    <limit effort="100" lower="-1.570796" upper="1.570796" velocity="100"/>
    <parent link="mid_left_cox"/>
    <child link="mid_left_femur"/>
  </joint>
  <joint name="mid_left_retract_joint" type="revolute">
    <origin rpy="0 0 0" xyz="-0.029923 0.039696 -0.018563"/>
    <parent link="mid_left_femur"/>
    <child link="mid_left_tibia"/>
    <axis xyz="0.707029 0.707185 0.0"/>
    <limit effort="100" lower="-1.570796" upper="1.570796" velocity="100"/>
  </joint>
  <link name="mid_left_cox">
    <inertial>
      <origin rpy="0 0 0" xyz="0.0012733261090569089 0.014903434394979126 -0.02034582182041162"/>
      <mass value="0.01391683496290758"/>
      <inertia ixx="3e-06" ixy="-0.0" ixz="0.0" iyy="4e-06" iyz="0.0" izz="3e-06"/>
    </inertial>
    <visual>
      <origin rpy="0 0 0" xyz="-0.003612 -0.056729 -0.0306"/>
      <geometry>
        <mesh filename="file:///home/mustafayousif/Code/hexapod_robot_harmonic/install/hexapod_description/share/hexapod_description/meshes/leg/cox_left_mid.stl" scale="0.001 0.001 0.001"/>
      </geometry>
      <material name="dark"/>
    </visual>
    <collision>
      <origin rpy="0 0 0" xyz="-0.003612 -0.056729 -0.0306"/>
      <geometry>
        <mesh filename="file:///home/mustafayousif/Code/hexapod_robot_harmonic/install/hexapod_description/share/hexapod_description/meshes/leg/cox_left_mid.stl" scale="0.001 0.001 0.001"/>
      </geometry>
    </collision>
  </link>
  <link name="mid_left_tibia">
    <inertial>
      <origin rpy="0 0 0" xyz="0.015589179677926173 0.010695585608516162 -0.0223992522730315"/>
      <mass value="0.012279438354877548"/>
      <inertia ixx="5e-06" ixy="0.0" ixz="0.0" iyy="6e-06" iyz="-1e-06" izz="2e-06"/>
    </inertial>
    <visual>
      <origin rpy="0 0 0" xyz="0.005374 -0.126425 0.009767"/>
      <geometry>
        <mesh filename="file:///home/mustafayousif/Code/hexapod_robot_harmonic/install/hexapod_description/share/hexapod_description/meshes/leg/tibia_left_mid.stl" scale="0.001 0.001 0.001"/>
      </geometry>
      <material name="dark"/>
    </visual>
    <collision>
      <origin rpy="0 0 0" xyz="0.005374 -0.126425 0.009767"/>
      <geometry>
        <mesh filename="file:///home/mustafayousif/Code/hexapod_robot_harmonic/install/hexapod_description/share/hexapod_description/meshes/leg/tibia_left_mid.stl" scale="0.001 0.001 0.001"/>
      </geometry>
    </collision>
  </link>
  <link name="mid_left_femur">
    <inertial>
      <origin rpy="0 0 0" xyz="-0.015011654934717145 0.020989624323966824 -0.005728252734904802"/>
      <mass value="0.018823784549799234"/>
      <inertia ixx="5e-06" ixy="0.0" ixz="-0.0" iyy="3e-06" iyz="2e-06" izz="5e-06"/>
    </inertial>
    <visual>
      <origin rpy="0 0 0" xyz="-0.024549 -0.086729 -0.008796"/>
      <geometry>
        <mesh filename="file:///home/mustafayousif/Code/hexapod_robot_harmonic/install/hexapod_description/share/hexapod_description/meshes/leg/femur_left_mid.stl" scale="0.001 0.001 0.001"/>
      </geometry>
      <material name="dark"/>
    </visual>
    <collision>
      <origin rpy="0 0 0" xyz="-0.024549 -0.086729 -0.008796"/>
      <geometry>
        <mesh filename="file:///home/mustafayousif/Code/hexapod_robot_harmonic/install/hexapod_description/share/hexapod_description/meshes/leg/femur_left_mid.stl" scale="0.001 0.001 0.001"/>
      </geometry>
    </collision>
  </link>
  <transmission name="mid_left_rotate_joint_tran">
    <type>transmission_interface/SimpleTransmission</type>
    <joint name="mid_left_rotate_joint">
      <hardwareInterface>hardware_interface/EffortJointInterface</hardwareInterface>
    </joint>
    <actuator name="mid_left_rotate_joint_actr">
      <hardwareInterface>hardware_interface/EffortJointInterface</hardwareInterface>
      <mechanicalReduction>1</mechanicalReduction>
    </actuator>
  </transmission>
  <transmission name="mid_left_abduct_joint_tran">
    <type>transmission_interface/SimpleTransmission</type>
    <joint name="mid_left_abduct_joint">
      <hardwareInterface>hardware_interface/EffortJointInterface</hardwareInterface>
    </joint>
    <actuator name="mid_left_abduct_joint_actr">
      <hardwareInterface>hardware_interface/EffortJointInterface</hardwareInterface>
      <mechanicalReduction>1</mechanicalReduction>
    </actuator>
  </transmission>
  <transmission name="mid_left_retract_joint_tran">
    <type>transmission_interface/SimpleTransmission</type>
    <joint name="mid_left_retract_joint">
      <hardwareInterface>hardware_interface/EffortJointInterface</hardwareInterface>
    </joint>
    <actuator name="mid_left_retract_joint_actr">
      <hardwareInterface>hardware_interface/EffortJointInterface</hardwareInterface>
      <mechanicalReduction>1</mechanicalReduction>
    </actuator>
  </transmission>
  <!-- Joints -->
  <joint name="bottom_left_rotate_joint" type="revolute">
    <origin rpy="0 0 0.785398185" xyz="-0.067095 0.047401 0.0297"/>
    <parent link="base_link"/>
    <child link="bottom_left_cox"/>
    <axis xyz="-0.0 0.0 -1.0"/>
    <limit effort="100" lower="-1.570796" upper="1.570796" velocity="100"/>
  </joint>
  <joint name="bottom_left_abduct_joint" type="revolute">
    <origin rpy="0 0 0" xyz="0.020937 0.03 -0.021804"/>
    <axis xyz="-1.0 -0.0 -0.0"/>
    <limit effort="100" lower="-1.570796" upper="1.570796" velocity="100"/>
    <parent link="bottom_left_cox"/>
    <child link="bottom_left_femur"/>
  </joint>
  <joint name="bottom_left_retract_joint" type="revolute">
    <origin rpy="0 0 0" xyz="-0.029923 0.039696 -0.018563"/>
    <parent link="bottom_left_femur"/>
    <child link="bottom_left_tibia"/>
    <axis xyz="0.707029 0.707185 0.0"/>
    <limit effort="100" lower="-1.570796" upper="1.570796" velocity="100"/>
  </joint>
  <link name="bottom_left_cox">
    <inertial>
      <origin rpy="0 0 0" xyz="0.0012733261090569089 0.014903434394979126 -0.02034582182041162"/>
      <mass value="0.01391683496290758"/>
      <inertia ixx="3e-06" ixy="-0.0" ixz="0.0" iyy="4e-06" iyz="0.0" izz="3e-06"/>
    </inertial>
    <visual>
      <origin rpy="0 0 0" xyz="-0.003612 -0.056729 -0.0306"/>
      <geometry>
        <mesh filename="file:///home/mustafayousif/Code/hexapod_robot_harmonic/install/hexapod_description/share/hexapod_description/meshes/leg/cox_left_mid.stl" scale="0.001 0.001 0.001"/>
      </geometry>
      <material name="dark"/>
    </visual>
    <collision>
      <origin rpy="0 0 0" xyz="-0.003612 -0.056729 -0.0306"/>
      <geometry>
        <mesh filename="file:///home/mustafayousif/Code/hexapod_robot_harmonic/install/hexapod_description/share/hexapod_description/meshes/leg/cox_left_mid.stl" scale="0.001 0.001 0.001"/>
      </geometry>
    </collision>
  </link>
  <link name="bottom_left_tibia">
    <inertial>
      <origin rpy="0 0 0" xyz="0.015589179677926173 0.010695585608516162 -0.0223992522730315"/>
      <mass value="0.012279438354877548"/>
      <inertia ixx="5e-06" ixy="0.0" ixz="0.0" iyy="6e-06" iyz="-1e-06" izz="2e-06"/>
    </inertial>
    <visual>
      <origin rpy="0 0 0" xyz="0.005374 -0.126425 0.009767"/>
      <geometry>
        <mesh filename="file:///home/mustafayousif/Code/hexapod_robot_harmonic/install/hexapod_description/share/hexapod_description/meshes/leg/tibia_left_mid.stl" scale="0.001 0.001 0.001"/>
      </geometry>
      <material name="dark"/>
    </visual>
    <collision>
      <origin rpy="0 0 0" xyz="0.005374 -0.126425 0.009767"/>
      <geometry>
        <mesh filename="file:///home/mustafayousif/Code/hexapod_robot_harmonic/install/hexapod_description/share/hexapod_description/meshes/leg/tibia_left_mid.stl" scale="0.001 0.001 0.001"/>
      </geometry>
    </collision>
  </link>
  <link name="bottom_left_femur">
    <inertial>
      <origin rpy="0 0 0" xyz="-0.015011654934717145 0.020989624323966824 -0.005728252734904802"/>
      <mass value="0.018823784549799234"/>
      <inertia ixx="5e-06" ixy="0.0" ixz="-0.0" iyy="3e-06" iyz="2e-06" izz="5e-06"/>
    </inertial>
    <visual>
      <origin rpy="0 0 0" xyz="-0.024549 -0.086729 -0.008796"/>
      <geometry>
        <mesh filename="file:///home/mustafayousif/Code/hexapod_robot_harmonic/install/hexapod_description/share/hexapod_description/meshes/leg/femur_left_mid.stl" scale="0.001 0.001 0.001"/>
      </geometry>
      <material name="dark"/>
    </visual>
    <collision>
      <origin rpy="0 0 0" xyz="-0.024549 -0.086729 -0.008796"/>
      <geometry>
        <mesh filename="file:///home/mustafayousif/Code/hexapod_robot_harmonic/install/hexapod_description/share/hexapod_description/meshes/leg/femur_left_mid.stl" scale="0.001 0.001 0.001"/>
      </geometry>
    </collision>
  </link>
  <transmission name="bottom_left_rotate_joint_tran">
    <type>transmission_interface/SimpleTransmission</type>
    <joint name="bottom_left_rotate_joint">
      <hardwareInterface>hardware_interface/EffortJointInterface</hardwareInterface>
    </joint>
    <actuator name="bottom_left_rotate_joint_actr">
      <hardwareInterface>hardware_interface/EffortJointInterface</hardwareInterface>
      <mechanicalReduction>1</mechanicalReduction>
    </actuator>
  </transmission>
  <transmission name="bottom_left_abduct_joint_tran">
    <type>transmission_interface/SimpleTransmission</type>
    <joint name="bottom_left_abduct_joint">
      <hardwareInterface>hardware_interface/EffortJointInterface</hardwareInterface>
    </joint>
    <actuator name="bottom_left_abduct_joint_actr">
      <hardwareInterface>hardware_interface/EffortJointInterface</hardwareInterface>
      <mechanicalReduction>1</mechanicalReduction>
    </actuator>
  </transmission>
  <transmission name="bottom_left_retract_joint_tran">
    <type>transmission_interface/SimpleTransmission</type>
    <joint name="bottom_left_retract_joint">
      <hardwareInterface>hardware_interface/EffortJointInterface</hardwareInterface>
    </joint>
    <actuator name="bottom_left_retract_joint_actr">
      <hardwareInterface>hardware_interface/EffortJointInterface</hardwareInterface>
      <mechanicalReduction>1</mechanicalReduction>
    </actuator>
  </transmission>
  <!-- Joints -->
  <joint name="top_right_rotate_joint" type="revolute">
    <origin rpy="0 0 3.926990925" xyz="0.075633 -0.046741 0.0297"/>
    <parent link="base_link"/>
    <child link="top_right_cox"/>
    <axis xyz="-0.0 0.0 -1.0"/>
    <limit effort="100" lower="-1.570796" upper="1.570796" velocity="100"/>
  </joint>
  <joint name="top_right_abduct_joint" type="revolute">
    <origin rpy="0 0 0" xyz="0.020937 0.03 -0.021804"/>
    <axis xyz="-1.0 -0.0 -0.0"/>
    <limit effort="100" lower="-1.570796" upper="1.570796" velocity="100"/>
    <parent link="top_right_cox"/>
    <child link="top_right_femur"/>
  </joint>
  <joint name="top_right_retract_joint" type="revolute">
    <origin rpy="0 0 0" xyz="-0.029923 0.039696 -0.018563"/>
    <parent link="top_right_femur"/>
    <child link="top_right_tibia"/>
    <axis xyz="0.707029 0.707185 0.0"/>
    <limit effort="100" lower="-1.570796" upper="1.570796" velocity="100"/>
  </joint>
  <link name="top_right_cox">
    <inertial>
      <origin rpy="0 0 0" xyz="0.0012733261090569089 0.014903434394979126 -0.02034582182041162"/>
      <mass value="0.01391683496290758"/>
      <inertia ixx="3e-06" ixy="-0.0" ixz="0.0" iyy="4e-06" iyz="0.0" izz="3e-06"/>
    </inertial>
    <visual>
      <origin rpy="0 0 0" xyz="-0.003612 -0.056729 -0.0306"/>
      <geometry>
        <mesh filename="file:///home/mustafayousif/Code/hexapod_robot_harmonic/install/hexapod_description/share/hexapod_description/meshes/leg/cox_left_mid.stl" scale="0.001 0.001 0.001"/>
      </geometry>
      <material name="dark"/>
    </visual>
    <collision>
      <origin rpy="0 0 0" xyz="-0.003612 -0.056729 -0.0306"/>
      <geometry>
        <mesh filename="file:///home/mustafayousif/Code/hexapod_robot_harmonic/install/hexapod_description/share/hexapod_description/meshes/leg/cox_left_mid.stl" scale="0.001 0.001 0.001"/>
      </geometry>
    </collision>
  </link>
  <link name="top_right_tibia">
    <inertial>
      <origin rpy="0 0 0" xyz="0.015589179677926173 0.010695585608516162 -0.0223992522730315"/>
      <mass value="0.012279438354877548"/>
      <inertia ixx="5e-06" ixy="0.0" ixz="0.0" iyy="6e-06" iyz="-1e-06" izz="2e-06"/>
    </inertial>
    <visual>
      <origin rpy="0 0 0" xyz="0.005374 -0.126425 0.009767"/>
      <geometry>
        <mesh filename="file:///home/mustafayousif/Code/hexapod_robot_harmonic/install/hexapod_description/share/hexapod_description/meshes/leg/tibia_left_mid.stl" scale="0.001 0.001 0.001"/>
      </geometry>
      <material name="dark"/>
    </visual>
    <collision>
      <origin rpy="0 0 0" xyz="0.005374 -0.126425 0.009767"/>
      <geometry>
        <mesh filename="file:///home/mustafayousif/Code/hexapod_robot_harmonic/install/hexapod_description/share/hexapod_description/meshes/leg/tibia_left_mid.stl" scale="0.001 0.001 0.001"/>
      </geometry>
    </collision>
  </link>
  <link name="top_right_femur">
    <inertial>
      <origin rpy="0 0 0" xyz="-0.015011654934717145 0.020989624323966824 -0.005728252734904802"/>
      <mass value="0.018823784549799234"/>
      <inertia ixx="5e-06" ixy="0.0" ixz="-0.0" iyy="3e-06" iyz="2e-06" izz="5e-06"/>
    </inertial>
    <visual>
      <origin rpy="0 0 0" xyz="-0.024549 -0.086729 -0.008796"/>
      <geometry>
        <mesh filename="file:///home/mustafayousif/Code/hexapod_robot_harmonic/install/hexapod_description/share/hexapod_description/meshes/leg/femur_left_mid.stl" scale="0.001 0.001 0.001"/>
      </geometry>
      <material name="dark"/>
    </visual>
    <collision>
      <origin rpy="0 0 0" xyz="-0.024549 -0.086729 -0.008796"/>
      <geometry>
        <mesh filename="file:///home/mustafayousif/Code/hexapod_robot_harmonic/install/hexapod_description/share/hexapod_description/meshes/leg/femur_left_mid.stl" scale="0.001 0.001 0.001"/>
      </geometry>
    </collision>
  </link>
  <transmission name="top_right_rotate_joint_tran">
    <type>transmission_interface/SimpleTransmission</type>
    <joint name="top_right_rotate_joint">
      <hardwareInterface>hardware_interface/EffortJointInterface</hardwareInterface>
    </joint>
    <actuator name="top_right_rotate_joint_actr">
      <hardwareInterface>hardware_interface/EffortJointInterface</hardwareInterface>
      <mechanicalReduction>1</mechanicalReduction>
    </actuator>
  </transmission>
  <transmission name="top_right_abduct_joint_tran">
    <type>transmission_interface/SimpleTransmission</type>
    <joint name="top_right_abduct_joint">
      <hardwareInterface>hardware_interface/EffortJointInterface</hardwareInterface>
    </joint>
    <actuator name="top_right_abduct_joint_actr">
      <hardwareInterface>hardware_interface/EffortJointInterface</hardwareInterface>
      <mechanicalReduction>1</mechanicalReduction>
    </actuator>
  </transmission>
  <transmission name="top_right_retract_joint_tran">
    <type>transmission_interface/SimpleTransmission</type>
    <joint name="top_right_retract_joint">
      <hardwareInterface>hardware_interface/EffortJointInterface</hardwareInterface>
    </joint>
    <actuator name="top_right_retract_joint_actr">
      <hardwareInterface>hardware_interface/EffortJointInterface</hardwareInterface>
      <mechanicalReduction>1</mechanicalReduction>
    </actuator>
  </transmission>
  <!-- Joints -->
  <joint name="mid_right_rotate_joint" type="revolute">
    <origin rpy="0 0 3.14159274" xyz="0.003574 -0.054899 0.0306"/>
    <parent link="base_link"/>
    <child link="mid_right_cox"/>
    <axis xyz="-0.0 0.0 -1.0"/>
    <limit effort="100" lower="-1.570796" upper="1.570796" velocity="100"/>
  </joint>
  <joint name="mid_right_abduct_joint" type="revolute">
    <origin rpy="0 0 0" xyz="0.020937 0.03 -0.021804"/>
    <axis xyz="-1.0 -0.0 -0.0"/>
    <limit effort="100" lower="-1.570796" upper="1.570796" velocity="100"/>
    <parent link="mid_right_cox"/>
    <child link="mid_right_femur"/>
  </joint>
  <joint name="mid_right_retract_joint" type="revolute">
    <origin rpy="0 0 0" xyz="-0.029923 0.039696 -0.018563"/>
    <parent link="mid_right_femur"/>
    <child link="mid_right_tibia"/>
    <axis xyz="0.707029 0.707185 0.0"/>
    <limit effort="100" lower="-1.570796" upper="1.570796" velocity="100"/>
  </joint>
  <link name="mid_right_cox">
    <inertial>
      <origin rpy="0 0 0" xyz="0.0012733261090569089 0.014903434394979126 -0.02034582182041162"/>
      <mass value="0.01391683496290758"/>
      <inertia ixx="3e-06" ixy="-0.0" ixz="0.0" iyy="4e-06" iyz="0.0" izz="3e-06"/>
    </inertial>
    <visual>
      <origin rpy="0 0 0" xyz="-0.003612 -0.056729 -0.0306"/>
      <geometry>
        <mesh filename="file:///home/mustafayousif/Code/hexapod_robot_harmonic/install/hexapod_description/share/hexapod_description/meshes/leg/cox_left_mid.stl" scale="0.001 0.001 0.001"/>
      </geometry>
      <material name="dark"/>
    </visual>
    <collision>
      <origin rpy="0 0 0" xyz="-0.003612 -0.056729 -0.0306"/>
      <geometry>
        <mesh filename="file:///home/mustafayousif/Code/hexapod_robot_harmonic/install/hexapod_description/share/hexapod_description/meshes/leg/cox_left_mid.stl" scale="0.001 0.001 0.001"/>
      </geometry>
    </collision>
  </link>
  <link name="mid_right_tibia">
    <inertial>
      <origin rpy="0 0 0" xyz="0.015589179677926173 0.010695585608516162 -0.0223992522730315"/>
      <mass value="0.012279438354877548"/>
      <inertia ixx="5e-06" ixy="0.0" ixz="0.0" iyy="6e-06" iyz="-1e-06" izz="2e-06"/>
    </inertial>
    <visual>
      <origin rpy="0 0 0" xyz="0.005374 -0.126425 0.009767"/>
      <geometry>
        <mesh filename="file:///home/mustafayousif/Code/hexapod_robot_harmonic/install/hexapod_description/share/hexapod_description/meshes/leg/tibia_left_mid.stl" scale="0.001 0.001 0.001"/>
      </geometry>
      <material name="dark"/>
    </visual>
    <collision>
      <origin rpy="0 0 0" xyz="0.005374 -0.126425 0.009767"/>
      <geometry>
        <mesh filename="file:///home/mustafayousif/Code/hexapod_robot_harmonic/install/hexapod_description/share/hexapod_description/meshes/leg/tibia_left_mid.stl" scale="0.001 0.001 0.001"/>
      </geometry>
    </collision>
  </link>
  <link name="mid_right_femur">
    <inertial>
      <origin rpy="0 0 0" xyz="-0.015011654934717145 0.020989624323966824 -0.005728252734904802"/>
      <mass value="0.018823784549799234"/>
      <inertia ixx="5e-06" ixy="0.0" ixz="-0.0" iyy="3e-06" iyz="2e-06" izz="5e-06"/>
    </inertial>
    <visual>
      <origin rpy="0 0 0" xyz="-0.024549 -0.086729 -0.008796"/>
      <geometry>
        <mesh filename="file:///home/mustafayousif/Code/hexapod_robot_harmonic/install/hexapod_description/share/hexapod_description/meshes/leg/femur_left_mid.stl" scale="0.001 0.001 0.001"/>
      </geometry>
      <material name="dark"/>
    </visual>
    <collision>
      <origin rpy="0 0 0" xyz="-0.024549 -0.086729 -0.008796"/>
      <geometry>
        <mesh filename="file:///home/mustafayousif/Code/hexapod_robot_harmonic/install/hexapod_description/share/hexapod_description/meshes/leg/femur_left_mid.stl" scale="0.001 0.001 0.001"/>
      </geometry>
    </collision>
  </link>
  <transmission name="mid_right_rotate_joint_tran">
    <type>transmission_interface/SimpleTransmission</type>
    <joint name="mid_right_rotate_joint">
      <hardwareInterface>hardware_interface/EffortJointInterface</hardwareInterface>
    </joint>
    <actuator name="mid_right_rotate_joint_actr">
      <hardwareInterface>hardware_interface/EffortJointInterface</hardwareInterface>
      <mechanicalReduction>1</mechanicalReduction>
    </actuator>
  </transmission>
  <transmission name="mid_right_abduct_joint_tran">
    <type>transmission_interface/SimpleTransmission</type>
    <joint name="mid_right_abduct_joint">
      <hardwareInterface>hardware_interface/EffortJointInterface</hardwareInterface>
    </joint>
    <actuator name="mid_right_abduct_joint_actr">
      <hardwareInterface>hardware_interface/EffortJointInterface</hardwareInterface>
      <mechanicalReduction>1</mechanicalReduction>
    </actuator>
  </transmission>
  <transmission name="mid_right_retract_joint_tran">
    <type>transmission_interface/SimpleTransmission</type>
    <joint name="mid_right_retract_joint">
      <hardwareInterface>hardware_interface/EffortJointInterface</hardwareInterface>
    </joint>
    <actuator name="mid_right_retract_joint_actr">
      <hardwareInterface>hardware_interface/EffortJointInterface</hardwareInterface>
      <mechanicalReduction>1</mechanicalReduction>
    </actuator>
  </transmission>
  <!-- Joints -->
  <joint name="bottom_right_rotate_joint" type="revolute">
    <origin rpy="0 0 2.356194555" xyz="-0.067095 -0.046741 0.0297"/>
    <parent link="base_link"/>
    <child link="bottom_right_cox"/>
    <axis xyz="-0.0 0.0 -1.0"/>
    <limit effort="100" lower="-1.570796" upper="1.570796" velocity="100"/>
  </joint>
  <joint name="bottom_right_abduct_joint" type="revolute">
    <origin rpy="0 0 0" xyz="0.020937 0.03 -0.021804"/>
    <axis xyz="-1.0 -0.0 -0.0"/>
    <limit effort="100" lower="-1.570796" upper="1.570796" velocity="100"/>
    <parent link="bottom_right_cox"/>
    <child link="bottom_right_femur"/>
  </joint>
  <joint name="bottom_right_retract_joint" type="revolute">
    <origin rpy="0 0 0" xyz="-0.029923 0.039696 -0.018563"/>
    <parent link="bottom_right_femur"/>
    <child link="bottom_right_tibia"/>
    <axis xyz="0.707029 0.707185 0.0"/>
    <limit effort="100" lower="-1.570796" upper="1.570796" velocity="100"/>
  </joint>
  <link name="bottom_right_cox">
    <inertial>
      <origin rpy="0 0 0" xyz="0.0012733261090569089 0.014903434394979126 -0.02034582182041162"/>
      <mass value="0.01391683496290758"/>
      <inertia ixx="3e-06" ixy="-0.0" ixz="0.0" iyy="4e-06" iyz="0.0" izz="3e-06"/>
    </inertial>
    <visual>
      <origin rpy="0 0 0" xyz="-0.003612 -0.056729 -0.0306"/>
      <geometry>
        <mesh filename="file:///home/mustafayousif/Code/hexapod_robot_harmonic/install/hexapod_description/share/hexapod_description/meshes/leg/cox_left_mid.stl" scale="0.001 0.001 0.001"/>
      </geometry>
      <material name="dark"/>
    </visual>
    <collision>
      <origin rpy="0 0 0" xyz="-0.003612 -0.056729 -0.0306"/>
      <geometry>
        <mesh filename="file:///home/mustafayousif/Code/hexapod_robot_harmonic/install/hexapod_description/share/hexapod_description/meshes/leg/cox_left_mid.stl" scale="0.001 0.001 0.001"/>
      </geometry>
    </collision>
  </link>
  <link name="bottom_right_tibia">
    <inertial>
      <origin rpy="0 0 0" xyz="0.015589179677926173 0.010695585608516162 -0.0223992522730315"/>
      <mass value="0.012279438354877548"/>
      <inertia ixx="5e-06" ixy="0.0" ixz="0.0" iyy="6e-06" iyz="-1e-06" izz="2e-06"/>
    </inertial>
    <visual>
      <origin rpy="0 0 0" xyz="0.005374 -0.126425 0.009767"/>
      <geometry>
        <mesh filename="file:///home/mustafayousif/Code/hexapod_robot_harmonic/install/hexapod_description/share/hexapod_description/meshes/leg/tibia_left_mid.stl" scale="0.001 0.001 0.001"/>
      </geometry>
      <material name="dark"/>
    </visual>
    <collision>
      <origin rpy="0 0 0" xyz="0.005374 -0.126425 0.009767"/>
      <geometry>
        <mesh filename="file:///home/mustafayousif/Code/hexapod_robot_harmonic/install/hexapod_description/share/hexapod_description/meshes/leg/tibia_left_mid.stl" scale="0.001 0.001 0.001"/>
      </geometry>
    </collision>
  </link>
  <link name="bottom_right_femur">
    <inertial>
      <origin rpy="0 0 0" xyz="-0.015011654934717145 0.020989624323966824 -0.005728252734904802"/>
      <mass value="0.018823784549799234"/>
      <inertia ixx="5e-06" ixy="0.0" ixz="-0.0" iyy="3e-06" iyz="2e-06" izz="5e-06"/>
    </inertial>
    <visual>
      <origin rpy="0 0 0" xyz="-0.024549 -0.086729 -0.008796"/>
      <geometry>
        <mesh filename="file:///home/mustafayousif/Code/hexapod_robot_harmonic/install/hexapod_description/share/hexapod_description/meshes/leg/femur_left_mid.stl" scale="0.001 0.001 0.001"/>
      </geometry>
      <material name="dark"/>
    </visual>
    <collision>
      <origin rpy="0 0 0" xyz="-0.024549 -0.086729 -0.008796"/>
      <geometry>
        <mesh filename="file:///home/mustafayousif/Code/hexapod_robot_harmonic/install/hexapod_description/share/hexapod_description/meshes/leg/femur_left_mid.stl" scale="0.001 0.001 0.001"/>
      </geometry>
    </collision>
  </link>
  <transmission name="bottom_right_rotate_joint_tran">
    <type>transmission_interface/SimpleTransmission</type>
    <joint name="bottom_right_rotate_joint">
      <hardwareInterface>hardware_interface/EffortJointInterface</hardwareInterface>
    </joint>
    <actuator name="bottom_right_rotate_joint_actr">
      <hardwareInterface>hardware_interface/EffortJointInterface</hardwareInterface>
      <mechanicalReduction>1</mechanicalReduction>
    </actuator>
  </transmission>
  <transmission name="bottom_right_abduct_joint_tran">
    <type>transmission_interface/SimpleTransmission</type>
    <joint name="bottom_right_abduct_joint">
      <hardwareInterface>hardware_interface/EffortJointInterface</hardwareInterface>
    </joint>
    <actuator name="bottom_right_abduct_joint_actr">
      <hardwareInterface>hardware_interface/EffortJointInterface</hardwareInterface>
      <mechanicalReduction>1</mechanicalReduction>
    </actuator>
  </transmission>
  <transmission name="bottom_right_retract_joint_tran">
    <type>transmission_interface/SimpleTransmission</type>
    <joint name="bottom_right_retract_joint">
      <hardwareInterface>hardware_interface/EffortJointInterface</hardwareInterface>
    </joint>
    <actuator name="bottom_right_retract_joint_actr">
      <hardwareInterface>hardware_interface/EffortJointInterface</hardwareInterface>
      <mechanicalReduction>1</mechanicalReduction>
    </actuator>
  </transmission>
  <!-- =============== Gazebo =============== -->
  <gazebo>
    <plugin filename="gz-sim-sensors-system" name="gz::sim::systems::Sensors">
      <render_engine>ogre2</render_engine>
    </plugin>
  </gazebo>
  <ros2_control name="GazeboSystem" type="system">
    <hardware>
      <plugin>gz_ros2_control/GazeboSimSystem</plugin>
    </hardware>
    <joint name="arm_rotator_joint">
      <command_interface name="position">
        <param name="min">-1</param>
        <param name="max">1</param>
      </command_interface>
      <state_interface name="position"/>
    </joint>
    <joint name="arm_abductor_joint">
      <command_interface name="position">
        <param name="min">-1</param>
        <param name="max">1</param>
      </command_interface>
      <state_interface name="position"/>
    </joint>
    <joint name="arm_retractor_joint">
      <command_interface name="position">
        <param name="min">-1</param>
        <param name="max">1</param>
      </command_interface>
      <state_interface name="position"/>
    </joint>
    <joint name="top_left_rotate_joint">
      <command_interface name="position">
        <param name="min">-1</param>
        <param name="max">1</param>
      </command_interface>
      <state_interface name="position"/>
    </joint>
    <joint name="top_left_abduct_joint">
      <command_interface name="position">
        <param name="min">-1</param>
        <param name="max">1</param>
      </command_interface>
      <state_interface name="position"/>
    </joint>
    <joint name="top_left_retract_joint">
      <command_interface name="position">
        <param name="min">-1</param>
        <param name="max">1</param>
      </command_interface>
      <state_interface name="position"/>
    </joint>
    <joint name="mid_left_rotate_joint">
      <command_interface name="position">
        <param name="min">-1</param>
        <param name="max">1</param>
      </command_interface>
      <state_interface name="position"/>
    </joint>
    <joint name="mid_left_abduct_joint">
      <command_interface name="position">
        <param name="min">-1</param>
        <param name="max">1</param>
      </command_interface>
      <state_interface name="position"/>
    </joint>
    <joint name="mid_left_retract_joint">
      <command_interface name="position">
        <param name="min">-1</param>
        <param name="max">1</param>
      </command_interface>
      <state_interface name="position"/>
    </joint>
    <joint name="bottom_left_rotate_joint">
      <command_interface name="position">
        <param name="min">-1</param>
        <param name="max">1</param>
      </command_interface>
      <state_interface name="position"/>
    </joint>
    <joint name="bottom_left_abduct_joint">
      <command_interface name="position">
        <param name="min">-1</param>
        <param name="max">1</param>
      </command_interface>
      <state_interface name="position"/>
    </joint>
    <joint name="bottom_left_retract_joint">
      <command_interface name="position">
        <param name="min">-1</param>
        <param name="max">1</param>
      </command_interface>
      <state_interface name="position"/>
    </joint>
    <joint name="top_right_rotate_joint">
      <command_interface name="position">
        <param name="min">-1</param>
        <param name="max">1</param>
      </command_interface>
      <state_interface name="position"/>
    </joint>
    <joint name="top_right_abduct_joint">
      <command_interface name="position">
        <param name="min">-1</param>
        <param name="max">1</param>
      </command_interface>
      <state_interface name="position"/>
    </joint>
    <joint name="top_right_retract_joint">
      <command_interface name="position">
        <param name="min">-1</param>
        <param name="max">1</param>
      </command_interface>
      <state_interface name="position"/>
    </joint>
    <joint name="mid_right_rotate_joint">
      <command_interface name="position">
        <param name="min">-1</param>
        <param name="max">1</param>
      </command_interface>
      <state_interface name="position"/>
    </joint>
    <joint name="mid_right_abduct_joint">
      <command_interface name="position">
        <param name="min">-1</param>
        <param name="max">1</param>
      </command_interface>
      <state_interface name="position"/>
    </joint>
    <joint name="mid_right_retract_joint">
      <command_interface name="position">
        <param name="min">-1</param>
        <param name="max">1</param>
      </command_interface>
      <state_interface name="position"/>
    </joint>
    <joint name="bottom_right_rotate_joint">
      <command_interface name="position">
        <param name="min">-1</param>
        <param name="max">1</param>
      </command_interface>
      <state_interface name="position"/>
    </joint>
    <joint name="bottom_right_abduct_joint">
      <command_interface name="position">
        <param name="min">-1</param>
        <param name="max">1</param>
      </command_interface>
      <state_interface name="position"/>
    </joint>
    <joint name="bottom_right_retract_joint">
      <command_interface name="position">
        <param name="min">-1</param>
        <param name="max">1</param>
      </command_interface>
      <state_interface name="position"/>
    </joint>
  </ros2_control>
</robot>
