<?xml version="1.0" encoding="UTF-8"?>
<robot xmlns:xacro="http://ros.org/wiki/xacro">
  <xacro:macro name="arm" params="parent *joint_origin">
    <!-- Joints -->
    <joint name="arm_base_mount_joint" type="fixed">
      <xacro:insert_block name="joint_origin"></xacro:insert_block>
      <parent link="${parent}"></parent>
      <child link="arm_base"></child>
    </joint>
    <joint name="arm_rotator_joint" type="continuous">
      <origin rpy="0 0 0" xyz="8.8e-05 0.019999 0.02995"></origin>
      <parent link="arm_base"></parent>
      <child link="arm_rotator"></child>
      <axis xyz="0.0 -0.0 -1.0"></axis>
      <limit effort="100" lower="-1.570796" upper="1.570796" velocity="100"></limit>
    </joint>
    <joint name="arm_abductor_joint" type="revolute">
      <origin rpy="0 0 0" xyz="0.014582 0.00069 0.013923"></origin>
      <parent link="arm_rotator"></parent>
      <child link="arm_abductor"></child>
      <axis xyz="-1.0 0.0 -0.0"></axis>
      <limit effort="100" lower="-1.570796" upper="1.570796" velocity="100"></limit>
    </joint>
    <joint name="arm_retractor_joint" type="revolute"><origin rpy="0 0 0" xyz="-0.000401 0.0 0.046709"></origin> <parent link="arm_abductor"></parent> <child link="arm_retractor"></child> <axis xyz="-0.999993 0.0 -0.003676"></axis> p <limit effort="100" lower="-1.570796" upper="1.570796" velocity="100"></limit></joint>
    <!-- Links -->
    <link name="arm_rotator">
      <inertial>
        <origin rpy="0 0 0" xyz="-0.00046642883527773724 0.0027188082250819237 0.00576546998065737"></origin>
        <mass value="0.02623546025799875"></mass>
        <inertia ixx="4e-06" ixy="0.0" ixz="0.0" iyy="4e-06" iyz="-0.0" izz="5e-06"></inertia>
      </inertial>
      <visual>
        <origin rpy="0 0 0" xyz="-0.025676 -0.000576 -0.07485"></origin>
        <geometry>
          <mesh filename="${meshes}/visual/rotator.stl" scale="0.001 0.001 0.001"></mesh>
        </geometry>
        <material name="PLA"></material>
      </visual>
      <collision>
        <origin rpy="0 0 0" xyz="-0.025676 -0.000576 -0.07485"></origin>
        <geometry>
          <mesh filename="${meshes}/collision/rotator.stl" scale="0.001 0.001 0.001"></mesh>
        </geometry>
      </collision>
    </link>
    <link name="arm_abductor">
      <inertial>
        <origin rpy="0 0 0" xyz="-0.014167725035919117 3.5639852713031765e-07 0.031090662760010462"></origin>
        <mass value="0.016534189067873267"></mass>
        <inertia ixx="5e-06" ixy="-0.0" ixz="1e-06" iyy="7e-06" iyz="-0.0" izz="2e-06"></inertia>
      </inertial>
      <visual>
        <origin rpy="0 0 0" xyz="-0.040258 -0.001266 -0.088773"></origin>
        <geometry>
          <mesh filename="${meshes}/visual/abductor.stl" scale="0.001 0.001 0.001"></mesh>
        </geometry>
        <material name="PLA"></material>
      </visual>
      <collision>
        <origin rpy="0 0 0" xyz="-0.040258 -0.001266 -0.088773"></origin>
        <geometry>
          <mesh filename="${meshes}/collision/abductor.stl" scale="0.001 0.001 0.001"></mesh>
        </geometry>
      </collision>
    </link>
    <link name="arm_retractor">
      <inertial>
        <origin rpy="0 0 0" xyz="-0.011027322351092845 -5.220911472792085e-05 0.023364114206742087"></origin>
        <mass value="0.015328010788351278"></mass>
        <inertia ixx="3e-06" ixy="0.0" ixz="-0.0" iyy="5e-06" iyz="0.0" izz="4e-06"></inertia>
      </inertial>
      <visual>
        <origin rpy="0 0 0" xyz="-0.039857 -0.001266 -0.135482"></origin>
        <geometry>
          <mesh filename="${meshes}/visual/retractor.stl" scale="0.001 0.001 0.001"></mesh>
        </geometry>
        <material name="PLA"></material>
      </visual>
      <collision>
        <origin rpy="0 0 0" xyz="-0.039857 -0.001266 -0.135482"></origin>
        <geometry>
          <mesh filename="${meshes}/collision/retractor.stl" scale="0.001 0.001 0.001"></mesh>
        </geometry>
      </collision>
    </link>
    <link name="arm_base">
      <inertial>
        <origin rpy="0 0 0" xyz="0.004115093716825637 0.020000308654227843 0.01035421864114821"></origin>
        <mass value="0.014628769254330782"></mass>
        <inertia ixx="2e-06" ixy="0.0" ixz="-0.0" iyy="3e-06" iyz="0.0" izz="2e-06"></inertia>
      </inertial>
      <visual>
        <origin rpy="0 0 0" xyz="-0.025588 0.019423 -0.0449"></origin>
        <geometry>
          <mesh filename="${meshes}/visual/base.stl" scale="0.001 0.001 0.001"></mesh>
        </geometry>
        <material name="PLA"></material>
      </visual>
      <collision>
        <origin rpy="0 0 0" xyz="-0.025588 0.019423 -0.0449"></origin>
        <geometry>
          <mesh filename="${meshes}/collision/base.stl" scale="0.001 0.001 0.001"></mesh>
        </geometry>
      </collision>
    </link>
  </xacro:macro>
</robot>
